Workbook

Sheet Grafica
B1: Bomba centrífuga ER-3407 · 1450 rpm · Curvas de HEAD y eficiencia digitalizadas
B2: Celdas amarillas = valores a introducir. Todo lo demás se calcula con el polinomio de la curva Ø649 mm.
B4: CÁLCULO 1 · Caudal → HEAD (curva Ø649 mm)
B5: Punto | C5: Caudal Q (m³/h) ► INTRODUCIR | D5: HEAD H (m) ◄ calculado Ø649 | E5: Estado
B6: P1 | C6: 900 | D6: =IF(ISNUMBER(C6),(a0_649+a1_649*C6+a2_649*C6^2+a3_649*C6^3),"") -> 243.69742 | E6: =IF(ISNUMBER(C6),IF(OR(C6<0,C6>Qmax_649),"Fuera de rango (extrapolado)","OK"),"") -> OK
B7: P2 | C7: 1000 | D7: =IF(ISNUMBER(C7),(a0_649+a1_649*C7+a2_649*C7^2+a3_649*C7^3),"") -> 215.9932 | E7: =IF(ISNUMBER(C7),IF(OR(C7<0,C7>Qmax_649),"Fuera de rango (extrapolado)","OK"),"") -> OK
B8: P3 | C8: 1100 | D8: =IF(ISNUMBER(C8),(a0_649+a1_649*C8+a2_649*C8^2+a3_649*C8^3),"") -> 181.28847 | E8: =IF(ISNUMBER(C8),IF(OR(C8<0,C8>Qmax_649),"Fuera de rango (extrapolado)","OK"),"") -> OK
B10: CÁLCULO 2 · HEAD → Caudal (curva Ø649 mm)
B11: Punto | C11: HEAD H (m) ► INTRODUCIR | D11: Caudal Q (m³/h) ◄ calculado Ø649 | E11: Estado
B12: G1 | C12: 240 | D12: =IF(ISNUMBER(C12),IF(AND(C12<=a0_649,C12>=(a0_649+a1_649*Qmax_649+a2_649*Qmax_649^2+a3_649*Qmax_649^3)),Datos_Curvas!$CJ$5,"Fuera de rango"),"") -> 914.81872 | E12: =IF(ISNUMBER(C12),IF(AND(C12<=a0_649,C12>=(a0_649+a1_649*Qmax_649+a2_649*Qmax_649^2+a3_649*Qmax_649^3)),"OK","H fuera de la curva Ø649"),"") -> OK
B13: G2 | C13: 215 | D13: =IF(ISNUMBER(C13),IF(AND(C13<=a0_649,C13>=(a0_649+a1_649*Qmax_649+a2_649*Qmax_649^2+a3_649*Qmax_649^3)),Datos_Curvas!$CJ$6,"Fuera de rango"),"") -> 1003.1862 | E13: =IF(ISNUMBER(C13),IF(AND(C13<=a0_649,C13>=(a0_649+a1_649*Qmax_649+a2_649*Qmax_649^2+a3_649*Qmax_649^3)),"OK","H fuera de la curva Ø649"),"") -> OK
B14: G3 | C14: 190 | D14: =IF(ISNUMBER(C14),IF(AND(C14<=a0_649,C14>=(a0_649+a1_649*Qmax_649+a2_649*Qmax_649^2+a3_649*Qmax_649^3)),Datos_Curvas!$CJ$7,"Fuera de rango"),"") -> 1076.8251 | E14: =IF(ISNUMBER(C14),IF(AND(C14<=a0_649,C14>=(a0_649+a1_649*Qmax_649+a2_649*Qmax_649^2+a3_649*Qmax_649^3)),"OK","H fuera de la curva Ø649"),"") -> OK
B16: PUNTOS DE REFERENCIA
B17: Punto | C17: Caudal Q (m³/h) | D17: HEAD H (m) | E17: H según curva Ø649 (m)
B18: BEP Ø635 (η 81 %) | C18: 820 | D18: 220 | E18: =(Polinomios!$B$7+Polinomios!$C$7*C18+Polinomios!$D$7*C18^2+Polinomios!$E$7*C18^3) -> 219.99983
B19: Bomba 3 | C19: 1040 | D19: 203 | E19: =(a0_649+a1_649*C19+a2_649*C19^2+a3_649*C19^3) -> 203
B20: Bomba 4 | C20: 970 | D20: 225 | E20: =(a0_649+a1_649*C20+a2_649*C20^2+a3_649*C20^3) -> 225
B21: Valores de los puntos de referencia: datos dados por el usuario.
B23: ECUACIÓN CURVA Ø649 mm
B24: ="H = "&TEXT(a0_649,"0.000")&" "&TEXT(a1_649,"+0.000000;-0.000000")&"·Q "&TEXT(a2_649,"+0.000E+00;-0.000E+00")&"·Q² "&TEXT(a3_649,"+0.000E+00;-0.000E+00")&"·Q³" -> H = 321.309 -0.044779·Q +8.421E-05·Q² -1.447E-07·Q³
B25: Construcción: H649(Q) = k·H635(Q/s), k = 1.1752, s = 1.0173, ajustada para pasar exactamente por Bomba 3 y Bomba 4. Ojo: por leyes de afinidad, pasar de Ø635 a Ø649 daría k ≈ 1,045; los puntos medidos requieren k ≈ 1.175 (equivale a ~688 mm teóricos). Puede deberse a velocidad real ≠ 1450 rpm, error de medida o calibración de manómetros.

Sheet Polinomios
A1: Coeficientes de los polinomios digitalizados (curva de fabricante ER-3407, 1450 rpm)
A2: Curvas de HEAD: H(Q) = a0 + a1·Q + a2·Q² + a3·Q³ (Q en m³/h, H en m)
A4: Diámetro impulsor (mm) | B4: a0 | C4: a1 | D4: a2 | E4: a3 | F4: Q mín (m³/h) | G4: Q máx (m³/h) | H4: Origen de los datos
A5: 508 | B5: 159.54772 | C5: -0.017704571 | D5: 3.6086415e-05 | E5: -1.3778869e-07 | F5: 0 | G5: 850 | H5: Digitalizado de la gráfica del fabricante (ajuste cúbico por mínimos cuadrados)
A6: 572 | B6: 219.97482 | C6: -0.026964169 | D6: 6.480424e-05 | E6: -1.4431077e-07 | F6: 0 | G6: 975 | H6: Digitalizado de la gráfica del fabricante (ajuste cúbico por mínimos cuadrados)
A7: 635 | B7: 273.41447 | C7: -0.038761723 | D7: 7.4149615e-05 | E7: -1.296561e-07 | F7: 0 | G7: 1104 | H7: Digitalizado; ajuste forzado a pasar por el BEP (820; 220) dado por el usuario
A8: 649 | B8: 321.30924 | C8: -0.044778912 | D8: 8.4206984e-05 | E8: -1.4474412e-07 | F8: 0 | G8: 1130 | H8: Extrapolado de Ø635: H649(Q)=k·H635(Q/s), con k=1.1752 y s=1.0173, que pasa por Bomba 3 (1040; 203) y Bomba 4 (970; 225)
A10: Curvas de EFICIENCIA (iso-rendimiento): Q(H) = b0 + b1·H + b2·H² + b3·H³ (cada curva en U se divide en rama izquierda y rama derecha)
A11: Rama | B11: Eficiencia η (%) | C11: b0 | D11: b1 | E11: b2 | F11: b3 | G11: H inicio (m) | H11: H fin (m) | I11: Nota
A12: Izquierda 60 % | B12: 60 | C12: 304.03587 | D12: -0.39538943 | E12: 0.0023134904 | F12: 0 | G12: 153.83 | H12: 263.02 | I12: Empieza sobre la curva Ø508 y termina sobre la curva Ø635 (límites por intersección)
A13: Izquierda 65 % | B13: 65 | C13: 416.79019 | D13: -0.78301506 | E13: 0.0031254115 | F13: 0 | G13: 150.97 | H13: 260.39 | I13: Empieza sobre la curva Ø508 y termina sobre la curva Ø635 (límites por intersección)
A14: Izquierda 70 % | B14: 70 | C14: 408.77087 | D14: -0.14735291 | E14: 0.0019692096 | F14: 0 | G14: 147.66 | H14: 256.34 | I14: Empieza sobre la curva Ø508 y termina sobre la curva Ø635 (límites por intersección)
A15: Izquierda 75 % | B15: 75 | C15: 506.59465 | D15: -0.57797528 | E15: 0.0035964206 | F15: 0 | G15: 142.72 | H15: 250 | I15: Empieza sobre la curva Ø508 y termina sobre la curva Ø635 (límites por intersección)
A16: Izquierda 78 % | B16: 78 | C16: 570.60788 | D16: -0.67075685 | E16: 0.0041796677 | F16: 0 | G16: 137.05 | H16: 243.41 | I16: Empieza sobre la curva Ø508 y termina sobre la curva Ø635 (límites por intersección)
A17: Izquierda 79 % | B17: 79 | C17: 687.05951 | D17: -1.2728041 | E17: 0.0055699843 | F17: 0 | G17: 130.16 | H17: 238.16 | I17: Empieza sobre la curva Ø508 y termina sobre la curva Ø635 (límites por intersección)
A18: Izquierda 80 % | B18: 80 | C18: 7219.6972 | D18: -92.90093 | E18: 0.43893867 | F18: -0.00068572956 | G18: 172 | H18: 234.31 | I18: Lazo cerrado: ambas ramas se unen en (737; 172); termina sobre Ø635
A19: Derecha 80 % | B19: 80 | C19: -2734.4861 | D19: 33.686985 | E19: -0.078511193 | F19: 0 | G19: 172 | H19: 209.06 | I19: Lazo cerrado: ambas ramas se unen en (737; 172); termina sobre Ø635
A20: Derecha 79 % | B20: 79 | C20: -2619.7226 | D20: 53.526979 | E20: -0.2842927 | F20: 0.00052539709 | G20: 124.84 | H20: 200.13 | I20: Empieza sobre la curva Ø508 y termina sobre la curva Ø635 (límites por intersección)
A21: Derecha 78 % | B21: 78 | C21: -166.46047 | D21: 11.348273 | E21: -0.038872095 | F21: 5.1933725e-05 | G21: 116.12 | H21: 192.71 | I21: Empieza sobre la curva Ø508 y termina sobre la curva Ø635 (límites por intersección)
A22: Derecha 75 % | B22: 75 | C22: 4.8722403 | D22: 9.2358456 | E22: -0.023892355 | F22: 1.8797341e-05 | G22: 108.5 | H22: 179.03 | I22: Empieza sobre la curva Ø508 y termina sobre la curva Ø635 (límites por intersección)
A23: Derecha 70 % | B23: 70 | C23: -544.86589 | D23: 24.184078 | E23: -0.14018465 | F23: 0.0003239391 | G23: 99.52 | H23: 160.15 | I23: Empieza sobre la curva Ø508 y termina sobre la curva Ø635 (límites por intersección)
A24: Derecha 65 % | B24: 65 | C24: 602.73384 | D24: 0.91063851 | E24: 0.031446567 | F24: -9.7645598e-05 | G24: 85.79 | H24: 146.51 | I24: Empieza sobre la curva Ø508 y termina sobre la curva Ø635 (límites por intersección)
A26: Notas:
A27: • Los coeficientes en azul son resultados del ajuste (no se calculan en Excel). Las curvas de la hoja Datos_Curvas se generan con fórmulas a partir de ellos.
A28: • Escala de digitalización: 1 m³/h ≈ 0,777 px y 1 m ≈ 1,546 px en la imagen original; precisión estimada ±2 m en HEAD y ±5 m³/h en caudal.
A29: • La curva de 81 % se reduce al punto BEP (820; 220) sobre Ø635, como en la gráfica original.
A30: • Curva Ø649: por leyes de afinidad (H ∝ D²) se esperaría k ≈ (649/635)² = 1,045; los puntos de operación exigen k ≈ 1.175. Ver comentario en hoja Grafica.

Sheet Datos_Curvas
A1: Puntos generados con fórmulas a partir de los polinomios (hoja Polinomios). No editar: sirven de origen para la gráfica.
A3: Ø508 mm | D3: Ø572 mm | G3: Ø635 mm | J3: Ø649 mm | M3: η 60 % (izq.) | P3: η 65 % (izq.) | S3: η 70 % (izq.) | V3: η 75 % (izq.) | Y3: η 78 % (izq.) | AB3: η 79 % (izq.) | AE3: η 80 % (izq.) | AH3: η 80 % (der.) | AK3: η 79 % (der.) | AN3: η 78 % (der.) | AQ3: η 75 % (der.) | AT3: η 70 % (der.) | AW3: η 65 % (der.) | AZ3: Líneas guía de puntos de referencia | BI3: Inversión H → Q por Newton-Raphson sobre el polinomio Ø649 (Q_{n+1} = Q_n − (P(Q_n) − H)/P'(Q_n)), 25 iteraciones, Q₀ = Q máx | CL3: Puntos dinámicos para la gráfica (si la celda de entrada está vacía, el punto no se dibuja)
A4: Q (m³/h) | B4: H (m) | D4: Q (m³/h) | E4: H (m) | G4: Q (m³/h) | H4: H (m) | J4: Q (m³/h) | K4: H (m) | M4: Q (m³/h) | N4: H (m) | P4: Q (m³/h) | Q4: H (m) | S4: Q (m³/h) | T4: H (m) | V4: Q (m³/h) | W4: H (m) | Y4: Q (m³/h) | Z4: H (m) | AB4: Q (m³/h) | AC4: H (m) | AE4: Q (m³/h) | AF4: H (m) | AH4: Q (m³/h) | AI4: H (m) | AK4: Q (m³/h) | AL4: H (m) | AN4: Q (m³/h) | AO4: H (m) | AQ4: Q (m³/h) | AR4: H (m) | AT4: Q (m³/h) | AU4: H (m) | AW4: Q (m³/h) | AX4: H (m) | AZ4: BEP Ø635 (η 81 %) Q | BA4: BEP Ø635 (η 81 %) H | BC4: Bomba 3 Q | BD4: Bomba 3 H | BF4: Bomba 4 Q | BG4: Bomba 4 H | BI4: H objetivo | BJ4: Q0 | BK4: Q1 | BL4: Q2 | BM4: Q3 | BN4: Q4 | BO4: Q5 | BP4: Q6 | BQ4: Q7 | BR4: Q8 | BS4: Q9 | BT4: Q10 | BU4: Q11 | BV4: Q12 | BW4: Q13 | BX4: Q14 | BY4: Q15 | BZ4: Q16 | CA4: Q17 | CB4: Q18 | CC4: Q19 | CD4: Q20 | CE4: Q21 | CF4: Q22 | CG4: Q23 | CH4: Q24 | CI4: Q25 | CJ4: Q resultado | CL4: Q (cálc. 1) | CM4: H (cálc. 1) | CN4: Etiqueta 1 | CO4: Q (cálc. 2) | CP4: H (cálc. 2) | CQ4: Etiqueta 2
A5: =Polinomios!$F$5+0*(Polinomios!$G$5-Polinomios!$F$5)/40 -> 0 | B5: =(Polinomios!$B$5+Polinomios!$C$5*A5+Polinomios!$D$5*A5^2+Polinomios!$E$5*A5^3) -> 159.54772 | D5: =Polinomios!$F$6+0*(Polinomios!$G$6-Polinomios!$F$6)/40 -> 0 | E5: =(Polinomios!$B$6+Polinomios!$C$6*D5+Polinomios!$D$6*D5^2+Polinomios!$E$6*D5^3) -> 219.97482 | G5: =Polinomios!$F$7+0*(Polinomios!$G$7-Polinomios!$F$7)/40 -> 0 | H5: =(Polinomios!$B$7+Polinomios!$C$7*G5+Polinomios!$D$7*G5^2+Polinomios!$E$7*G5^3) -> 273.41447 | J5: =Polinomios!$F$8+0*(Polinomios!$G$8-Polinomios!$F$8)/40 -> 0 | K5: =(Polinomios!$B$8+Polinomios!$C$8*J5+Polinomios!$D$8*J5^2+Polinomios!$E$8*J5^3) -> 321.30924 | M5: =(Polinomios!$C$12+Polinomios!$D$12*N5+Polinomios!$E$12*N5^2+Polinomios!$F$12*N5^3) -> 297.95878 | N5: =Polinomios!$G$12+0*(Polinomios!$H$12-Polinomios!$G$12)/20 -> 153.83 | P5: =(Polinomios!$C$13+Polinomios!$D$13*Q5+Polinomios!$E$13*Q5^2+Polinomios!$F$13*Q5^3) -> 369.8126 | Q5: =Polinomios!$G$13+0*(Polinomios!$H$13-Polinomios!$G$13)/20 -> 150.97 | S5: =(Polinomios!$C$14+Polinomios!$D$14*T5+Polinomios!$E$14*T5^2+Polinomios!$F$14*T5^3) -> 429.94836 | T5: =Polinomios!$G$14+0*(Polinomios!$H$14-Polinomios!$G$14)/20 -> 147.66 | V5: =(Polinomios!$C$15+Polinomios!$D$15*W5+Polinomios!$E$15*W5^2+Polinomios!$F$15*W5^3) -> 497.36151 | W5: =Polinomios!$G$15+0*(Polinomios!$H$15-Polinomios!$G$15)/20 -> 142.72 | Y5: =(Polinomios!$C$16+Polinomios!$D$16*Z5+Polinomios!$E$16*Z5^2+Polinomios!$F$16*Z5^3) -> 557.18611 | Z5: =Polinomios!$G$16+0*(Polinomios!$H$16-Polinomios!$G$16)/20 -> 137.05 | AB5: =(Polinomios!$C$17+Polinomios!$D$17*AC5+Polinomios!$E$17*AC5^2+Polinomios!$F$17*AC5^3) -> 615.75592 | AC5: =Polinomios!$G$17+0*(Polinomios!$H$17-Polinomios!$G$17)/20 -> 130.16 | AE5: =(Polinomios!$C$18+Polinomios!$D$18*AF5+Polinomios!$E$18*AF5^2+Polinomios!$F$18*AF5^3) -> 736.99964 | AF5: =Polinomios!$G$18+0*(Polinomios!$H$18-Polinomios!$G$18)/20 -> 172 | AH5: =(Polinomios!$C$19+Polinomios!$D$19*AI5+Polinomios!$E$19*AI5^2+Polinomios!$F$19*AI5^3) -> 737.00027 | AI5: =Polinomios!$G$19+0*(Polinomios!$H$19-Polinomios!$G$19)/20 -> 172 | AK5: =(Polinomios!$C$20+Polinomios!$D$20*AL5+Polinomios!$E$20*AL5^2+Polinomios!$F$20*AL5^3) -> 654.1071 | AL5: =Polinomios!$G$20+0*(Polinomios!$H$20-Polinomios!$G$20)/20 -> 124.84 | AN5: =(Polinomios!$C$21+Polinomios!$D$21*AO5+Polinomios!$E$21*AO5^2+Polinomios!$F$21*AO5^3) -> 708.4703 | AO5: =Polinomios!$G$21+0*(Polinomios!$H$21-Polinomios!$G$21)/20 -> 116.12 | AQ5: =(Polinomios!$C$22+Polinomios!$D$22*AR5+Polinomios!$E$22*AR5^2+Polinomios!$F$22*AR5^3) -> 749.70435 | AR5: =Polinomios!$G$22+0*(Polinomios!$H$22-Polinomios!$G$22)/20 -> 108.5 | AT5: =(Polinomios!$C$23+Polinomios!$D$23*AU5+Polinomios!$E$23*AU5^2+Polinomios!$F$23*AU5^3) -> 792.8093 | AU5: =Polinomios!$G$23+0*(Polinomios!$H$23-Polinomios!$G$23)/20 -> 99.52 | AW5: =(Polinomios!$C$24+Polinomios!$D$24*AX5+Polinomios!$E$24*AX5^2+Polinomios!$F$24*AX5^3) -> 850.64766 | AX5: =Polinomios!$G$24+0*(Polinomios!$H$24-Polinomios!$G$24)/20 -> 85.79 | AZ5: 0 | BA5: =Grafica!$D$18 -> 220 | BC5: 0 | BD5: =Grafica!$D$19 -> 203 | BF5: 0 | BG5: =Grafica!$D$20 -> 225 | BI5: =Grafica!$C$12 -> 240 | BJ5: =Qmax_649 -> 1130 | BK5: =IF(ISNUMBER(BI5),MAX(0,BJ5-((a0_649+a1_649*BJ5+a2_649*BJ5^2+a3_649*BJ5^3)-BI5)/(a1_649+2*a2_649*BJ5+3*a3_649*BJ5^2)),0) -> 957.31582 | BL5: =IF(ISNUMBER(BI5),MAX(0,BK5-((a0_649+a1_649*BK5+a2_649*BK5^2+a3_649*BK5^3)-BI5)/(a1_649+2*a2_649*BK5+3*a3_649*BK5^2)),0) -> 916.90593 | BM5: =IF(ISNUMBER(BI5),MAX(0,BL5-((a0_649+a1_649*BL5+a2_649*BL5^2+a3_649*BL5^3)-BI5)/(a1_649+2*a2_649*BL5+3*a3_649*BL5^2)),0) -> 914.82407 | BN5: =IF(ISNUMBER(BI5),MAX(0,BM5-((a0_649+a1_649*BM5+a2_649*BM5^2+a3_649*BM5^3)-BI5)/(a1_649+2*a2_649*BM5+3*a3_649*BM5^2)),0) -> 914.81872 | BO5: =IF(ISNUMBER(BI5),MAX(0,BN5-((a0_649+a1_649*BN5+a2_649*BN5^2+a3_649*BN5^3)-BI5)/(a1_649+2*a2_649*BN5+3*a3_649*BN5^2)),0) -> 914.81872 | BP5: =IF(ISNUMBER(BI5),MAX(0,BO5-((a0_649+a1_649*BO5+a2_649*BO5^2+a3_649*BO5^3)-BI5)/(a1_649+2*a2_649*BO5+3*a3_649*BO5^2)),0) -> 914.81872 | BQ5: =IF(ISNUMBER(BI5),MAX(0,BP5-((a0_649+a1_649*BP5+a2_649*BP5^2+a3_649*BP5^3)-BI5)/(a1_649+2*a2_649*BP5+3*a3_649*BP5^2)),0) -> 914.81872 | BR5: =IF(ISNUMBER(BI5),MAX(0,BQ5-((a0_649+a1_649*BQ5+a2_649*BQ5^2+a3_649*BQ5^3)-BI5)/(a1_649+2*a2_649*BQ5+3*a3_649*BQ5^2)),0) -> 914.81872 | BS5: =IF(ISNUMBER(BI5),MAX(0,BR5-((a0_649+a1_649*BR5+a2_649*BR5^2+a3_649*BR5^3)-BI5)/(a1_649+2*a2_649*BR5+3*a3_649*BR5^2)),0) -> 914.81872 | BT5: =IF(ISNUMBER(BI5),MAX(0,BS5-((a0_649+a1_649*BS5+a2_649*BS5^2+a3_649*BS5^3)-BI5)/(a1_649+2*a2_649*BS5+3*a3_649*BS5^2)),0) -> 914.81872 | BU5: =IF(ISNUMBER(BI5),MAX(0,BT5-((a0_649+a1_649*BT5+a2_649*BT5^2+a3_649*BT5^3)-BI5)/(a1_649+2*a2_649*BT5+3*a3_649*BT5^2)),0) -> 914.81872 | BV5: =IF(ISNUMBER(BI5),MAX(0,BU5-((a0_649+a1_649*BU5+a2_649*BU5^2+a3_649*BU5^3)-BI5)/(a1_649+2*a2_649*BU5+3*a3_649*BU5^2)),0) -> 914.81872 | BW5: =IF(ISNUMBER(BI5),MAX(0,BV5-((a0_649+a1_649*BV5+a2_649*BV5^2+a3_649*BV5^3)-BI5)/(a1_649+2*a2_649*BV5+3*a3_649*BV5^2)),0) -> 914.81872 | BX5: =IF(ISNUMBER(BI5),MAX(0,BW5-((a0_649+a1_649*BW5+a2_649*BW5^2+a3_649*BW5^3)-BI5)/(a1_649+2*a2_649*BW5+3*a3_649*BW5^2)),0) -> 914.81872 | BY5: =IF(ISNUMBER(BI5),MAX(0,BX5-((a0_649+a1_649*BX5+a2_649*BX5^2+a3_649*BX5^3)-BI5)/(a1_649+2*a2_649*BX5+3*a3_649*BX5^2)),0) -> 914.81872 | BZ5: =IF(ISNUMBER(BI5),MAX(0,BY5-((a0_649+a1_649*BY5+a2_649*BY5^2+a3_649*BY5^3)-BI5)/(a1_649+2*a2_649*BY5+3*a3_649*BY5^2)),0) -> 914.81872 | CA5: =IF(ISNUMBER(BI5),MAX(0,BZ5-((a0_649+a1_649*BZ5+a2_649*BZ5^2+a3_649*BZ5^3)-BI5)/(a1_649+2*a2_649*BZ5+3*a3_649*BZ5^2)),0) -> 914.81872 | CB5: =IF(ISNUMBER(BI5),MAX(0,CA5-((a0_649+a1_649*CA5+a2_649*CA5^2+a3_649*CA5^3)-BI5)/(a1_649+2*a2_649*CA5+3*a3_649*CA5^2)),0) -> 914.81872 | CC5: =IF(ISNUMBER(BI5),MAX(0,CB5-((a0_649+a1_649*CB5+a2_649*CB5^2+a3_649*CB5^3)-BI5)/(a1_649+2*a2_649*CB5+3*a3_649*CB5^2)),0) -> 914.81872 | CD5: =IF(ISNUMBER(BI5),MAX(0,CC5-((a0_649+a1_649*CC5+a2_649*CC5^2+a3_649*CC5^3)-BI5)/(a1_649+2*a2_649*CC5+3*a3_649*CC5^2)),0) -> 914.81872 | CE5: =IF(ISNUMBER(BI5),MAX(0,CD5-((a0_649+a1_649*CD5+a2_649*CD5^2+a3_649*CD5^3)-BI5)/(a1_649+2*a2_649*CD5+3*a3_649*CD5^2)),0) -> 914.81872 | CF5: =IF(ISNUMBER(BI5),MAX(0,CE5-((a0_649+a1_649*CE5+a2_649*CE5^2+a3_649*CE5^3)-BI5)/(a1_649+2*a2_649*CE5+3*a3_649*CE5^2)),0) -> 914.81872 | CG5: =IF(ISNUMBER(BI5),MAX(0,CF5-((a0_649+a1_649*CF5+a2_649*CF5^2+a3_649*CF5^3)-BI5)/(a1_649+2*a2_649*CF5+3*a3_649*CF5^2)),0) -> 914.81872 | CH5: =IF(ISNUMBER(BI5),MAX(0,CG5-((a0_649+a1_649*CG5+a2_649*CG5^2+a3_649*CG5^3)-BI5)/(a1_649+2*a2_649*CG5+3*a3_649*CG5^2)),0) -> 914.81872 | CI5: =IF(ISNUMBER(BI5),MAX(0,CH5-((a0_649+a1_649*CH5+a2_649*CH5^2+a3_649*CH5^3)-BI5)/(a1_649+2*a2_649*CH5+3*a3_649*CH5^2)),0) -> 914.81872 | CJ5: =CI5 -> 914.81872 | CL5: =IF(ISNUMBER(Grafica!$C$6),Grafica!$C$6,NA()) -> 900 | CM5: =IF(ISNUMBER(Grafica!$D$6),Grafica!$D$6,NA()) -> 243.69742 | CN5: =IF(ISNUMBER(Grafica!$D$6),"P1: Q="&TEXT(Grafica!$C$6,"0")&" ; H="&TEXT(Grafica!$D$6,"0.0"),"P1") -> P1: Q=900 ; H=243.7 | CO5: =IF(ISNUMBER(Grafica!$D$12),Grafica!$D$12,NA()) -> 914.81872 | CP5: =IF(ISNUMBER(Grafica!$D$12),Grafica!$C$12,NA()) -> 240 | CQ5: =IF(ISNUMBER(Grafica!$D$12),"G1: Q="&TEXT(Grafica!$D$12,"0")&" ; H="&TEXT(Grafica!$C$12,"0.0"),"G1") -> G1: Q=915 ; H=240.0
A6: =Polinomios!$F$5+1*(Polinomios!$G$5-Polinomios!$F$5)/40 -> 21.25 | B6: =(Polinomios!$B$5+Polinomios!$C$5*A6+Polinomios!$D$5*A6^2+Polinomios!$E$5*A6^3) -> 159.18647 | D6: =Polinomios!$F$6+1*(Polinomios!$G$6-Polinomios!$F$6)/40 -> 24.375 | E6: =(Polinomios!$B$6+Polinomios!$C$6*D6+Polinomios!$D$6*D6^2+Polinomios!$E$6*D6^3) -> 219.35398 | G6: =Polinomios!$F$7+1*(Polinomios!$G$7-Polinomios!$F$7)/40 -> 27.6 | H6: =(Polinomios!$B$7+Polinomios!$C$7*G6+Polinomios!$D$7*G6^2+Polinomios!$E$7*G6^3) -> 272.3984 | J6: =Polinomios!$F$8+1*(Polinomios!$G$8-Polinomios!$F$8)/40 -> 28.25 | K6: =(Polinomios!$B$8+Polinomios!$C$8*J6+Polinomios!$D$8*J6^2+Polinomios!$E$8*J6^3) -> 320.10818 | M6: =(Polinomios!$C$12+Polinomios!$D$12*N6+Polinomios!$E$12*N6^2+Polinomios!$F$12*N6^3) -> 299.75501 | N6: =Polinomios!$G$12+1*(Polinomios!$H$12-Polinomios!$G$12)/20 -> 159.2895 | P6: =(Polinomios!$C$13+Polinomios!$D$13*Q6+Polinomios!$E$13*Q6^2+Polinomios!$F$13*Q6^3) -> 370.78519 | Q6: =Polinomios!$G$13+1*(Polinomios!$H$13-Polinomios!$G$13)/20 -> 156.441 | S6: =(Polinomios!$C$14+Polinomios!$D$14*T6+Polinomios!$E$14*T6^2+Polinomios!$F$14*T6^3) -> 432.36592 | T6: =Polinomios!$G$14+1*(Polinomios!$H$14-Polinomios!$G$14)/20 -> 153.094 | V6: =(Polinomios!$C$15+Polinomios!$D$15*W6+Polinomios!$E$15*W6^2+Polinomios!$F$15*W6^3) -> 499.87121 | W6: =Polinomios!$G$15+1*(Polinomios!$H$15-Polinomios!$G$15)/20 -> 148.084 | Y6: =(Polinomios!$C$16+Polinomios!$D$16*Z6+Polinomios!$E$16*Z6^2+Polinomios!$F$16*Z6^3) -> 559.82978 | Z6: =Polinomios!$G$16+1*(Polinomios!$H$16-Polinomios!$G$16)/20 -> 142.368 | AB6: =(Polinomios!$C$17+Polinomios!$D$17*AC6+Polinomios!$E$17*AC6^2+Polinomios!$F$17*AC6^3) -> 616.87508 | AC6: =Polinomios!$G$17+1*(Polinomios!$H$17-Polinomios!$G$17)/20 -> 135.56 | AE6: =(Polinomios!$C$18+Polinomios!$D$18*AF6+Polinomios!$E$18*AF6^2+Polinomios!$F$18*AF6^3) -> 729.18779 | AF6: =Polinomios!$G$18+1*(Polinomios!$H$18-Polinomios!$G$18)/20 -> 175.1155 | AH6: =(Polinomios!$C$19+Polinomios!$D$19*AI6+Polinomios!$E$19*AI6^2+Polinomios!$F$19*AI6^3) -> 749.10713 | AI6: =Polinomios!$G$19+1*(Polinomios!$H$19-Polinomios!$G$19)/20 -> 173.853 | AK6: =(Polinomios!$C$20+Polinomios!$D$20*AL6+Polinomios!$E$20*AL6^2+Polinomios!$F$20*AL6^3) -> 679.65952 | AL6: =Polinomios!$G$20+1*(Polinomios!$H$20-Polinomios!$G$20)/20 -> 128.6045 | AN6: =(Polinomios!$C$21+Polinomios!$D$21*AO6+Polinomios!$E$21*AO6^2+Polinomios!$F$21*AO6^3) -> 725.10028 | AO6: =Polinomios!$G$21+1*(Polinomios!$H$21-Polinomios!$G$21)/20 -> 119.9495 | AQ6: =(Polinomios!$C$22+Polinomios!$D$22*AR6+Polinomios!$E$22*AR6^2+Polinomios!$F$22*AR6^3) -> 766.11181 | AR6: =Polinomios!$G$22+1*(Polinomios!$H$22-Polinomios!$G$22)/20 -> 112.0265 | AT6: =(Polinomios!$C$23+Polinomios!$D$23*AU6+Polinomios!$E$23*AU6^2+Polinomios!$F$23*AU6^3) -> 810.32539 | AU6: =Polinomios!$G$23+1*(Polinomios!$H$23-Polinomios!$G$23)/20 -> 102.5515 | AW6: =(Polinomios!$C$24+Polinomios!$D$24*AX6+Polinomios!$E$24*AX6^2+Polinomios!$F$24*AX6^3) -> 863.3033 | AX6: =Polinomios!$G$24+1*(Polinomios!$H$24-Polinomios!$G$24)/20 -> 88.826 | AZ6: =Grafica!$C$18 -> 820 | BA6: =Grafica!$D$18 -> 220 | BC6: =Grafica!$C$19 -> 1040 | BD6: =Grafica!$D$19 -> 203 | BF6: =Grafica!$C$20 -> 970 | BG6: =Grafica!$D$20 -> 225 | BI6: =Grafica!$C$13 -> 215 | BJ6: =Qmax_649 -> 1130 | BK6: =IF(ISNUMBER(BI6),MAX(0,BJ6-((a0_649+a1_649*BJ6+a2_649*BJ6^2+a3_649*BJ6^3)-BI6)/(a1_649+2*a2_649*BJ6+3*a3_649*BJ6^2)),0) -> 1018.4491 | BL6: =IF(ISNUMBER(BI6),MAX(0,BK6-((a0_649+a1_649*BK6+a2_649*BK6^2+a3_649*BK6^3)-BI6)/(a1_649+2*a2_649*BK6+3*a3_649*BK6^2)),0) -> 1003.4423 | BM6: =IF(ISNUMBER(BI6),MAX(0,BL6-((a0_649+a1_649*BL6+a2_649*BL6^2+a3_649*BL6^3)-BI6)/(a1_649+2*a2_649*BL6+3*a3_649*BL6^2)),0) -> 1003.1863 | BN6: =IF(ISNUMBER(BI6),MAX(0,BM6-((a0_649+a1_649*BM6+a2_649*BM6^2+a3_649*BM6^3)-BI6)/(a1_649+2*a2_649*BM6+3*a3_649*BM6^2)),0) -> 1003.1862 | BO6: =IF(ISNUMBER(BI6),MAX(0,BN6-((a0_649+a1_649*BN6+a2_649*BN6^2+a3_649*BN6^3)-BI6)/(a1_649+2*a2_649*BN6+3*a3_649*BN6^2)),0) -> 1003.1862 | BP6: =IF(ISNUMBER(BI6),MAX(0,BO6-((a0_649+a1_649*BO6+a2_649*BO6^2+a3_649*BO6^3)-BI6)/(a1_649+2*a2_649*BO6+3*a3_649*BO6^2)),0) -> 1003.1862 | BQ6: =IF(ISNUMBER(BI6),MAX(0,BP6-((a0_649+a1_649*BP6+a2_649*BP6^2+a3_649*BP6^3)-BI6)/(a1_649+2*a2_649*BP6+3*a3_649*BP6^2)),0) -> 1003.1862 | BR6: =IF(ISNUMBER(BI6),MAX(0,BQ6-((a0_649+a1_649*BQ6+a2_649*BQ6^2+a3_649*BQ6^3)-BI6)/(a1_649+2*a2_649*BQ6+3*a3_649*BQ6^2)),0) -> 1003.1862 | BS6: =IF(ISNUMBER(BI6),MAX(0,BR6-((a0_649+a1_649*BR6+a2_649*BR6^2+a3_649*BR6^3)-BI6)/(a1_649+2*a2_649*BR6+3*a3_649*BR6^2)),0) -> 1003.1862 | BT6: =IF(ISNUMBER(BI6),MAX(0,BS6-((a0_649+a1_649*BS6+a2_649*BS6^2+a3_649*BS6^3)-BI6)/(a1_649+2*a2_649*BS6+3*a3_649*BS6^2)),0) -> 1003.1862 | BU6: =IF(ISNUMBER(BI6),MAX(0,BT6-((a0_649+a1_649*BT6+a2_649*BT6^2+a3_649*BT6^3)-BI6)/(a1_649+2*a2_649*BT6+3*a3_649*BT6^2)),0) -> 1003.1862 | BV6: =IF(ISNUMBER(BI6),MAX(0,BU6-((a0_649+a1_649*BU6+a2_649*BU6^2+a3_649*BU6^3)-BI6)/(a1_649+2*a2_649*BU6+3*a3_649*BU6^2)),0) -> 1003.1862 | BW6: =IF(ISNUMBER(BI6),MAX(0,BV6-((a0_649+a1_649*BV6+a2_649*BV6^2+a3_649*BV6^3)-BI6)/(a1_649+2*a2_649*BV6+3*a3_649*BV6^2)),0) -> 1003.1862 | BX6: =IF(ISNUMBER(BI6),MAX(0,BW6-((a0_649+a1_649*BW6+a2_649*BW6^2+a3_649*BW6^3)-BI6)/(a1_649+2*a2_649*BW6+3*a3_649*BW6^2)),0) -> 1003.1862 | BY6: =IF(ISNUMBER(BI6),MAX(0,BX6-((a0_649+a1_649*BX6+a2_649*BX6^2+a3_649*BX6^3)-BI6)/(a1_649+2*a2_649*BX6+3*a3_649*BX6^2)),0) -> 1003.1862 | BZ6: =IF(ISNUMBER(BI6),MAX(0,BY6-((a0_649+a1_649*BY6+a2_649*BY6^2+a3_649*BY6^3)-BI6)/(a1_649+2*a2_649*BY6+3*a3_649*BY6^2)),0) -> 1003.1862 | CA6: =IF(ISNUMBER(BI6),MAX(0,BZ6-((a0_649+a1_649*BZ6+a2_649*BZ6^2+a3_649*BZ6^3)-BI6)/(a1_649+2*a2_649*BZ6+3*a3_649*BZ6^2)),0) -> 1003.1862 | CB6: =IF(ISNUMBER(BI6),MAX(0,CA6-((a0_649+a1_649*CA6+a2_649*CA6^2+a3_649*CA6^3)-BI6)/(a1_649+2*a2_649*CA6+3*a3_649*CA6^2)),0) -> 1003.1862 | CC6: =IF(ISNUMBER(BI6),MAX(0,CB6-((a0_649+a1_649*CB6+a2_649*CB6^2+a3_649*CB6^3)-BI6)/(a1_649+2*a2_649*CB6+3*a3_649*CB6^2)),0) -> 1003.1862 | CD6: =IF(ISNUMBER(BI6),MAX(0,CC6-((a0_649+a1_649*CC6+a2_649*CC6^2+a3_649*CC6^3)-BI6)/(a1_649+2*a2_649*CC6+3*a3_649*CC6^2)),0) -> 1003.1862 | CE6: =IF(ISNUMBER(BI6),MAX(0,CD6-((a0_649+a1_649*CD6+a2_649*CD6^2+a3_649*CD6^3)-BI6)/(a1_649+2*a2_649*CD6+3*a3_649*CD6^2)),0) -> 1003.1862 | CF6: =IF(ISNUMBER(BI6),MAX(0,CE6-((a0_649+a1_649*CE6+a2_649*CE6^2+a3_649*CE6^3)-BI6)/(a1_649+2*a2_649*CE6+3*a3_649*CE6^2)),0) -> 1003.1862 | CG6: =IF(ISNUMBER(BI6),MAX(0,CF6-((a0_649+a1_649*CF6+a2_649*CF6^2+a3_649*CF6^3)-BI6)/(a1_649+2*a2_649*CF6+3*a3_649*CF6^2)),0) -> 1003.1862 | CH6: =IF(ISNUMBER(BI6),MAX(0,CG6-((a0_649+a1_649*CG6+a2_649*CG6^2+a3_649*CG6^3)-BI6)/(a1_649+2*a2_649*CG6+3*a3_649*CG6^2)),0) -> 1003.1862 | CI6: =IF(ISNUMBER(BI6),MAX(0,CH6-((a0_649+a1_649*CH6+a2_649*CH6^2+a3_649*CH6^3)-BI6)/(a1_649+2*a2_649*CH6+3*a3_649*CH6^2)),0) -> 1003.1862 | CJ6: =CI6 -> 1003.1862 | CL6: =IF(ISNUMBER(Grafica!$C$7),Grafica!$C$7,NA()) -> 1000 | CM6: =IF(ISNUMBER(Grafica!$D$7),Grafica!$D$7,NA()) -> 215.9932 | CN6: =IF(ISNUMBER(Grafica!$D$7),"P2: Q="&TEXT(Grafica!$C$7,"0")&" ; H="&TEXT(Grafica!$D$7,"0.0"),"P2") -> P2: Q=1000 ; H=216.0 | CO6: =IF(ISNUMBER(Grafica!$D$13),Grafica!$D$13,NA()) -> 1003.1862 | CP6: =IF(ISNUMBER(Grafica!$D$13),Grafica!$C$13,NA()) -> 215 | CQ6: =IF(ISNUMBER(Grafica!$D$13),"G2: Q="&TEXT(Grafica!$D$13,"0")&" ; H="&TEXT(Grafica!$C$13,"0.0"),"G2") -> G2: Q=1003 ; H=215.0
A7: =Polinomios!$F$5+2*(Polinomios!$G$5-Polinomios!$F$5)/40 -> 42.5 | B7: =(Polinomios!$B$5+Polinomios!$C$5*A7+Polinomios!$D$5*A7^2+Polinomios!$E$5*A7^3) -> 158.84988 | D7: =Polinomios!$F$6+2*(Polinomios!$G$6-Polinomios!$F$6)/40 -> 48.75 | E7: =(Polinomios!$B$6+Polinomios!$C$6*D7+Polinomios!$D$6*D7^2+Polinomios!$E$6*D7^3) -> 218.79761 | G7: =Polinomios!$F$7+2*(Polinomios!$G$7-Polinomios!$F$7)/40 -> 55.2 | H7: =(Polinomios!$B$7+Polinomios!$C$7*G7+Polinomios!$D$7*G7^2+Polinomios!$E$7*G7^3) -> 271.47895 | J7: =Polinomios!$F$8+2*(Polinomios!$G$8-Polinomios!$F$8)/40 -> 56.5 | K7: =(Polinomios!$B$8+Polinomios!$C$8*J7+Polinomios!$D$8*J7^2+Polinomios!$E$8*J7^3) -> 319.02194 | M7: =(Polinomios!$C$12+Polinomios!$D$12*N7+Polinomios!$E$12*N7^2+Polinomios!$F$12*N7^3) -> 301.68915 | N7: =Polinomios!$G$12+2*(Polinomios!$H$12-Polinomios!$G$12)/20 -> 164.749 | P7: =(Polinomios!$C$13+Polinomios!$D$13*Q7+Polinomios!$E$13*Q7^2+Polinomios!$F$13*Q7^3) -> 371.94487 | Q7: =Polinomios!$G$13+2*(Polinomios!$H$13-Polinomios!$G$13)/20 -> 161.912 | S7: =(Polinomios!$C$14+Polinomios!$D$14*T7+Polinomios!$E$14*T7^2+Polinomios!$F$14*T7^3) -> 434.89977 | T7: =Polinomios!$G$14+2*(Polinomios!$H$14-Polinomios!$G$14)/20 -> 158.528 | V7: =(Polinomios!$C$15+Polinomios!$D$15*W7+Polinomios!$E$15*W7^2+Polinomios!$F$15*W7^3) -> 502.58786 | W7: =Polinomios!$G$15+2*(Polinomios!$H$15-Polinomios!$G$15)/20 -> 153.448 | Y7: =(Polinomios!$C$16+Polinomios!$D$16*Z7+Polinomios!$E$16*Z7^2+Polinomios!$F$16*Z7^3) -> 562.70986 | Z7: =Polinomios!$G$16+2*(Polinomios!$H$16-Polinomios!$G$16)/20 -> 147.686 | AB7: =(Polinomios!$C$17+Polinomios!$D$17*AC7+Polinomios!$E$17*AC7^2+Polinomios!$F$17*AC7^3) -> 618.31908 | AC7: =Polinomios!$G$17+2*(Polinomios!$H$17-Polinomios!$G$17)/20 -> 140.96 | AE7: =(Polinomios!$C$18+Polinomios!$D$18*AF7+Polinomios!$E$18*AF7^2+Polinomios!$F$18*AF7^3) -> 722.90357 | AF7: =Polinomios!$G$18+2*(Polinomios!$H$18-Polinomios!$G$18)/20 -> 178.231 | AH7: =(Polinomios!$C$19+Polinomios!$D$19*AI7+Polinomios!$E$19*AI7^2+Polinomios!$F$19*AI7^3) -> 760.67484 | AI7: =Polinomios!$G$19+2*(Polinomios!$H$19-Polinomios!$G$19)/20 -> 175.706 | AK7: =(Polinomios!$C$20+Polinomios!$D$20*AL7+Polinomios!$E$20*AL7^2+Polinomios!$F$20*AL7^3) -> 702.8995 | AL7: =Polinomios!$G$20+2*(Polinomios!$H$20-Polinomios!$G$20)/20 -> 132.369 | AN7: =(Polinomios!$C$21+Polinomios!$D$21*AO7+Polinomios!$E$21*AO7^2+Polinomios!$F$21*AO7^3) -> 741.13828 | AO7: =Polinomios!$G$21+2*(Polinomios!$H$21-Polinomios!$G$21)/20 -> 123.779 | AQ7: =(Polinomios!$C$22+Polinomios!$D$22*AR7+Polinomios!$E$22*AR7^2+Polinomios!$F$22*AR7^3) -> 782.08214 | AR7: =Polinomios!$G$22+2*(Polinomios!$H$22-Polinomios!$G$22)/20 -> 115.553 | AT7: =(Polinomios!$C$23+Polinomios!$D$23*AU7+Polinomios!$E$23*AU7^2+Polinomios!$F$23*AU7^3) -> 827.09667 | AU7: =Polinomios!$G$23+2*(Polinomios!$H$23-Polinomios!$G$23)/20 -> 105.583 | AW7: =(Polinomios!$C$24+Polinomios!$D$24*AX7+Polinomios!$E$24*AX7^2+Polinomios!$F$24*AX7^3) -> 876.05896 | AX7: =Polinomios!$G$24+2*(Polinomios!$H$24-Polinomios!$G$24)/20 -> 91.862 | AZ7: =Grafica!$C$18 -> 820 | BA7: 0 | BC7: =Grafica!$C$19 -> 1040 | BD7: 0 | BF7: =Grafica!$C$20 -> 970 | BG7: 0 | BI7: =Grafica!$C$14 -> 190 | BJ7: =Qmax_649 -> 1130 | BK7: =IF(ISNUMBER(BI7),MAX(0,BJ7-((a0_649+a1_649*BJ7+a2_649*BJ7^2+a3_649*BJ7^3)-BI7)/(a1_649+2*a2_649*BJ7+3*a3_649*BJ7^2)),0) -> 1079.5824 | BL7: =IF(ISNUMBER(BI7),MAX(0,BK7-((a0_649+a1_649*BK7+a2_649*BK7^2+a3_649*BK7^3)-BI7)/(a1_649+2*a2_649*BK7+3*a3_649*BK7^2)),0) -> 1076.8331 | BM7: =IF(ISNUMBER(BI7),MAX(0,BL7-((a0_649+a1_649*BL7+a2_649*BL7^2+a3_649*BL7^3)-BI7)/(a1_649+2*a2_649*BL7+3*a3_649*BL7^2)),0) -> 1076.8251 | BN7: =IF(ISNUMBER(BI7),MAX(0,BM7-((a0_649+a1_649*BM7+a2_649*BM7^2+a3_649*BM7^3)-BI7)/(a1_649+2*a2_649*BM7+3*a3_649*BM7^2)),0) -> 1076.8251 | BO7: =IF(ISNUMBER(BI7),MAX(0,BN7-((a0_649+a1_649*BN7+a2_649*BN7^2+a3_649*BN7^3)-BI7)/(a1_649+2*a2_649*BN7+3*a3_649*BN7^2)),0) -> 1076.8251 | BP7: =IF(ISNUMBER(BI7),MAX(0,BO7-((a0_649+a1_649*BO7+a2_649*BO7^2+a3_649*BO7^3)-BI7)/(a1_649+2*a2_649*BO7+3*a3_649*BO7^2)),0) -> 1076.8251 | BQ7: =IF(ISNUMBER(BI7),MAX(0,BP7-((a0_649+a1_649*BP7+a2_649*BP7^2+a3_649*BP7^3)-BI7)/(a1_649+2*a2_649*BP7+3*a3_649*BP7^2)),0) -> 1076.8251 | BR7: =IF(ISNUMBER(BI7),MAX(0,BQ7-((a0_649+a1_649*BQ7+a2_649*BQ7^2+a3_649*BQ7^3)-BI7)/(a1_649+2*a2_649*BQ7+3*a3_649*BQ7^2)),0) -> 1076.8251 | BS7: =IF(ISNUMBER(BI7),MAX(0,BR7-((a0_649+a1_649*BR7+a2_649*BR7^2+a3_649*BR7^3)-BI7)/(a1_649+2*a2_649*BR7+3*a3_649*BR7^2)),0) -> 1076.8251 | BT7: =IF(ISNUMBER(BI7),MAX(0,BS7-((a0_649+a1_649*BS7+a2_649*BS7^2+a3_649*BS7^3)-BI7)/(a1_649+2*a2_649*BS7+3*a3_649*BS7^2)),0) -> 1076.8251 | BU7: =IF(ISNUMBER(BI7),MAX(0,BT7-((a0_649+a1_649*BT7+a2_649*BT7^2+a3_649*BT7^3)-BI7)/(a1_649+2*a2_649*BT7+3*a3_649*BT7^2)),0) -> 1076.8251 | BV7: =IF(ISNUMBER(BI7),MAX(0,BU7-((a0_649+a1_649*BU7+a2_649*BU7^2+a3_649*BU7^3)-BI7)/(a1_649+2*a2_649*BU7+3*a3_649*BU7^2)),0) -> 1076.8251 | BW7: =IF(ISNUMBER(BI7),MAX(0,BV7-((a0_649+a1_649*BV7+a2_649*BV7^2+a3_649*BV7^3)-BI7)/(a1_649+2*a2_649*BV7+3*a3_649*BV7^2)),0) -> 1076.8251 | BX7: =IF(ISNUMBER(BI7),MAX(0,BW7-((a0_649+a1_649*BW7+a2_649*BW7^2+a3_649*BW7^3)-BI7)/(a1_649+2*a2_649*BW7+3*a3_649*BW7^2)),0) -> 1076.8251 | BY7: =IF(ISNUMBER(BI7),MAX(0,BX7-((a0_649+a1_649*BX7+a2_649*BX7^2+a3_649*BX7^3)-BI7)/(a1_649+2*a2_649*BX7+3*a3_649*BX7^2)),0) -> 1076.8251 | BZ7: =IF(ISNUMBER(BI7),MAX(0,BY7-((a0_649+a1_649*BY7+a2_649*BY7^2+a3_649*BY7^3)-BI7)/(a1_649+2*a2_649*BY7+3*a3_649*BY7^2)),0) -> 1076.8251 | CA7: =IF(ISNUMBER(BI7),MAX(0,BZ7-((a0_649+a1_649*BZ7+a2_649*BZ7^2+a3_649*BZ7^3)-BI7)/(a1_649+2*a2_649*BZ7+3*a3_649*BZ7^2)),0) -> 1076.8251 | CB7: =IF(ISNUMBER(BI7),MAX(0,CA7-((a0_649+a1_649*CA7+a2_649*CA7^2+a3_649*CA7^3)-BI7)/(a1_649+2*a2_649*CA7+3*a3_649*CA7^2)),0) -> 1076.8251 | CC7: =IF(ISNUMBER(BI7),MAX(0,CB7-((a0_649+a1_649*CB7+a2_649*CB7^2+a3_649*CB7^3)-BI7)/(a1_649+2*a2_649*CB7+3*a3_649*CB7^2)),0) -> 1076.8251 | CD7: =IF(ISNUMBER(BI7),MAX(0,CC7-((a0_649+a1_649*CC7+a2_649*CC7^2+a3_649*CC7^3)-BI7)/(a1_649+2*a2_649*CC7+3*a3_649*CC7^2)),0) -> 1076.8251 | CE7: =IF(ISNUMBER(BI7),MAX(0,CD7-((a0_649+a1_649*CD7+a2_649*CD7^2+a3_649*CD7^3)-BI7)/(a1_649+2*a2_649*CD7+3*a3_649*CD7^2)),0) -> 1076.8251 | CF7: =IF(ISNUMBER(BI7),MAX(0,CE7-((a0_649+a1_649*CE7+a2_649*CE7^2+a3_649*CE7^3)-BI7)/(a1_649+2*a2_649*CE7+3*a3_649*CE7^2)),0) -> 1076.8251 | CG7: =IF(ISNUMBER(BI7),MAX(0,CF7-((a0_649+a1_649*CF7+a2_649*CF7^2+a3_649*CF7^3)-BI7)/(a1_649+2*a2_649*CF7+3*a3_649*CF7^2)),0) -> 1076.8251 | CH7: =IF(ISNUMBER(BI7),MAX(0,CG7-((a0_649+a1_649*CG7+a2_649*CG7^2+a3_649*CG7^3)-BI7)/(a1_649+2*a2_649*CG7+3*a3_649*CG7^2)),0) -> 1076.8251 | CI7: =IF(ISNUMBER(BI7),MAX(0,CH7-((a0_649+a1_649*CH7+a2_649*CH7^2+a3_649*CH7^3)-BI7)/(a1_649+2*a2_649*CH7+3*a3_649*CH7^2)),0) -> 1076.8251 | CJ7: =CI7 -> 1076.8251 | CL7: =IF(ISNUMBER(Grafica!$C$8),Grafica!$C$8,NA()) -> 1100 | CM7: =IF(ISNUMBER(Grafica!$D$8),Grafica!$D$8,NA()) -> 181.28847 | CN7: =IF(ISNUMBER(Grafica!$D$8),"P3: Q="&TEXT(Grafica!$C$8,"0")&" ; H="&TEXT(Grafica!$D$8,"0.0"),"P3") -> P3: Q=1100 ; H=181.3 | CO7: =IF(ISNUMBER(Grafica!$D$14),Grafica!$D$14,NA()) -> 1076.8251 | CP7: =IF(ISNUMBER(Grafica!$D$14),Grafica!$C$14,NA()) -> 190 | CQ7: =IF(ISNUMBER(Grafica!$D$14),"G3: Q="&TEXT(Grafica!$D$14,"0")&" ; H="&TEXT(Grafica!$C$14,"0.0"),"G3") -> G3: Q=1077 ; H=190.0
A8: =Polinomios!$F$5+3*(Polinomios!$G$5-Polinomios!$F$5)/40 -> 63.75 | B8: =(Polinomios!$B$5+Polinomios!$C$5*A8+Polinomios!$D$5*A8^2+Polinomios!$E$5*A8^3) -> 158.53001 | D8: =Polinomios!$F$6+3*(Polinomios!$G$6-Polinomios!$F$6)/40 -> 73.125 | E8: =(Polinomios!$B$6+Polinomios!$C$6*D8+Polinomios!$D$6*D8^2+Polinomios!$E$6*D8^3) -> 218.29316 | G8: =Polinomios!$F$7+3*(Polinomios!$G$7-Polinomios!$F$7)/40 -> 82.8 | H8: =(Polinomios!$B$7+Polinomios!$C$7*G8+Polinomios!$D$7*G8^2+Polinomios!$E$7*G8^3) -> 270.63976 | J8: =Polinomios!$F$8+3*(Polinomios!$G$8-Polinomios!$F$8)/40 -> 84.75 | K8: =(Polinomios!$B$8+Polinomios!$C$8*J8+Polinomios!$D$8*J8^2+Polinomios!$E$8*J8^3) -> 318.03094 | M8: =(Polinomios!$C$12+Polinomios!$D$12*N8+Polinomios!$E$12*N8^2+Polinomios!$F$12*N8^3) -> 303.7612 | N8: =Polinomios!$G$12+3*(Polinomios!$H$12-Polinomios!$G$12)/20 -> 170.2085 | P8: =(Polinomios!$C$13+Polinomios!$D$13*Q8+Polinomios!$E$13*Q8^2+Polinomios!$F$13*Q8^3) -> 373.29165 | Q8: =Polinomios!$G$13+3*(Polinomios!$H$13-Polinomios!$G$13)/20 -> 167.383 | S8: =(Polinomios!$C$14+Polinomios!$D$14*T8+Polinomios!$E$14*T8^2+Polinomios!$F$14*T8^3) -> 437.54992 | T8: =Polinomios!$G$14+3*(Polinomios!$H$14-Polinomios!$G$14)/20 -> 163.962 | V8: =(Polinomios!$C$15+Polinomios!$D$15*W8+Polinomios!$E$15*W8^2+Polinomios!$F$15*W8^3) -> 505.51147 | W8: =Polinomios!$G$15+3*(Polinomios!$H$15-Polinomios!$G$15)/20 -> 158.812 | Y8: =(Polinomios!$C$16+Polinomios!$D$16*Z8+Polinomios!$E$16*Z8^2+Polinomios!$F$16*Z8^3) -> 565.82636 | Z8: =Polinomios!$G$16+3*(Polinomios!$H$16-Polinomios!$G$16)/20 -> 153.004 | AB8: =(Polinomios!$C$17+Polinomios!$D$17*AC8+Polinomios!$E$17*AC8^2+Polinomios!$F$17*AC8^3) -> 620.08792 | AC8: =Polinomios!$G$17+3*(Polinomios!$H$17-Polinomios!$G$17)/20 -> 146.36 | AE8: =(Polinomios!$C$18+Polinomios!$D$18*AF8+Polinomios!$E$18*AF8^2+Polinomios!$F$18*AF8^3) -> 718.02258 | AF8: =Polinomios!$G$18+3*(Polinomios!$H$18-Polinomios!$G$18)/20 -> 181.3465 | AH8: =(Polinomios!$C$19+Polinomios!$D$19*AI8+Polinomios!$E$19*AI8^2+Polinomios!$F$19*AI8^3) -> 771.70339 | AI8: =Polinomios!$G$19+3*(Polinomios!$H$19-Polinomios!$G$19)/20 -> 177.559 | AK8: =(Polinomios!$C$20+Polinomios!$D$20*AL8+Polinomios!$E$20*AL8^2+Polinomios!$F$20*AL8^3) -> 723.99524 | AL8: =Polinomios!$G$20+3*(Polinomios!$H$20-Polinomios!$G$20)/20 -> 136.1335 | AN8: =(Polinomios!$C$21+Polinomios!$D$21*AO8+Polinomios!$E$21*AO8^2+Polinomios!$F$21*AO8^3) -> 756.60178 | AO8: =Polinomios!$G$21+3*(Polinomios!$H$21-Polinomios!$G$21)/20 -> 127.6085 | AQ8: =(Polinomios!$C$22+Polinomios!$D$22*AR8+Polinomios!$E$22*AR8^2+Polinomios!$F$22*AR8^3) -> 797.62029 | AR8: =Polinomios!$G$22+3*(Polinomios!$H$22-Polinomios!$G$22)/20 -> 119.0795 | AT8: =(Polinomios!$C$23+Polinomios!$D$23*AU8+Polinomios!$E$23*AU8^2+Polinomios!$F$23*AU8^3) -> 843.17727 | AU8: =Polinomios!$G$23+3*(Polinomios!$H$23-Polinomios!$G$23)/20 -> 108.6145 | AW8: =(Polinomios!$C$24+Polinomios!$D$24*AX8+Polinomios!$E$24*AX8^2+Polinomios!$F$24*AX8^3) -> 888.89825 | AX8: =Polinomios!$G$24+3*(Polinomios!$H$24-Polinomios!$G$24)/20 -> 94.898 | AZ8: =Grafica!$B$18&" ("&TEXT(Grafica!$C$18,"0")&" ; "&TEXT(Grafica!$D$18,"0")&")" -> BEP Ø635 (η 81 %) (820 ; 220) | BC8: =Grafica!$B$19&" ("&TEXT(Grafica!$C$19,"0")&" ; "&TEXT(Grafica!$D$19,"0")&")" -> Bomba 3 (1040 ; 203) | BF8: =Grafica!$B$20&" ("&TEXT(Grafica!$C$20,"0")&" ; "&TEXT(Grafica!$D$20,"0")&")" -> Bomba 4 (970 ; 225)
A9: =Polinomios!$F$5+4*(Polinomios!$G$5-Polinomios!$F$5)/40 -> 85 | B9: =(Polinomios!$B$5+Polinomios!$C$5*A9+Polinomios!$D$5*A9^2+Polinomios!$E$5*A9^3) -> 158.21894 | D9: =Polinomios!$F$6+4*(Polinomios!$G$6-Polinomios!$F$6)/40 -> 97.5 | E9: =(Polinomios!$B$6+Polinomios!$C$6*D9+Polinomios!$D$6*D9^2+Polinomios!$E$6*D9^3) -> 217.8281 | G9: =Polinomios!$F$7+4*(Polinomios!$G$7-Polinomios!$F$7)/40 -> 110.4 | H9: =(Polinomios!$B$7+Polinomios!$C$7*G9+Polinomios!$D$7*G9^2+Polinomios!$E$7*G9^3) -> 269.86446 | J9: =Polinomios!$F$8+4*(Polinomios!$G$8-Polinomios!$F$8)/40 -> 113 | K9: =(Polinomios!$B$8+Polinomios!$C$8*J9+Polinomios!$D$8*J9^2+Polinomios!$E$8*J9^3) -> 317.11561 | M9: =(Polinomios!$C$12+Polinomios!$D$12*N9+Polinomios!$E$12*N9^2+Polinomios!$F$12*N9^3) -> 305.97117 | N9: =Polinomios!$G$12+4*(Polinomios!$H$12-Polinomios!$G$12)/20 -> 175.668 | P9: =(Polinomios!$C$13+Polinomios!$D$13*Q9+Polinomios!$E$13*Q9^2+Polinomios!$F$13*Q9^3) -> 374.82553 | Q9: =Polinomios!$G$13+4*(Polinomios!$H$13-Polinomios!$G$13)/20 -> 172.854 | S9: =(Polinomios!$C$14+Polinomios!$D$14*T9+Polinomios!$E$14*T9^2+Polinomios!$F$14*T9^3) -> 440.31636 | T9: =Polinomios!$G$14+4*(Polinomios!$H$14-Polinomios!$G$14)/20 -> 169.396 | V9: =(Polinomios!$C$15+Polinomios!$D$15*W9+Polinomios!$E$15*W9^2+Polinomios!$F$15*W9^3) -> 508.64204 | W9: =Polinomios!$G$15+4*(Polinomios!$H$15-Polinomios!$G$15)/20 -> 164.176 | Y9: =(Polinomios!$C$16+Polinomios!$D$16*Z9+Polinomios!$E$16*Z9^2+Polinomios!$F$16*Z9^3) -> 569.17926 | Z9: =Polinomios!$G$16+4*(Polinomios!$H$16-Polinomios!$G$16)/20 -> 158.322 | AB9: =(Polinomios!$C$17+Polinomios!$D$17*AC9+Polinomios!$E$17*AC9^2+Polinomios!$F$17*AC9^3) -> 622.18161 | AC9: =Polinomios!$G$17+4*(Polinomios!$H$17-Polinomios!$G$17)/20 -> 151.76 | AE9: =(Polinomios!$C$18+Polinomios!$D$18*AF9+Polinomios!$E$18*AF9^2+Polinomios!$F$18*AF9^3) -> 714.4204 | AF9: =Polinomios!$G$18+4*(Polinomios!$H$18-Polinomios!$G$18)/20 -> 184.462 | AH9: =(Polinomios!$C$19+Polinomios!$D$19*AI9+Polinomios!$E$19*AI9^2+Polinomios!$F$19*AI9^3) -> 782.19279 | AI9: =Polinomios!$G$19+4*(Polinomios!$H$19-Polinomios!$G$19)/20 -> 179.412 | AK9: =(Polinomios!$C$20+Polinomios!$D$20*AL9+Polinomios!$E$20*AL9^2+Polinomios!$F$20*AL9^3) -> 743.1149 | AL9: =Polinomios!$G$20+4*(Polinomios!$H$20-Polinomios!$G$20)/20 -> 139.898 | AN9: =(Polinomios!$C$21+Polinomios!$D$21*AO9+Polinomios!$E$21*AO9^2+Polinomios!$F$21*AO9^3) -> 771.50829 | AO9: =Polinomios!$G$21+4*(Polinomios!$H$21-Polinomios!$G$21)/20 -> 131.438 | AQ9: =(Polinomios!$C$22+Polinomios!$D$22*AR9+Polinomios!$E$22*AR9^2+Polinomios!$F$22*AR9^3) -> 812.7312 | AR9: =Polinomios!$G$22+4*(Polinomios!$H$22-Polinomios!$G$22)/20 -> 122.606 | AT9: =(Polinomios!$C$23+Polinomios!$D$23*AU9+Polinomios!$E$23*AU9^2+Polinomios!$F$23*AU9^3) -> 858.62136 | AU9: =Polinomios!$G$23+4*(Polinomios!$H$23-Polinomios!$G$23)/20 -> 111.646 | AW9: =(Polinomios!$C$24+Polinomios!$D$24*AX9+Polinomios!$E$24*AX9^2+Polinomios!$F$24*AX9^3) -> 901.80479 | AX9: =Polinomios!$G$24+4*(Polinomios!$H$24-Polinomios!$G$24)/20 -> 97.934
A10: =Polinomios!$F$5+5*(Polinomios!$G$5-Polinomios!$F$5)/40 -> 106.25 | B10: =(Polinomios!$B$5+Polinomios!$C$5*A10+Polinomios!$D$5*A10^2+Polinomios!$E$5*A10^3) -> 157.90872 | D10: =Polinomios!$F$6+5*(Polinomios!$G$6-Polinomios!$F$6)/40 -> 121.875 | E10: =(Polinomios!$B$6+Polinomios!$C$6*D10+Polinomios!$D$6*D10^2+Polinomios!$E$6*D10^3) -> 217.38989 | G10: =Polinomios!$F$7+5*(Polinomios!$G$7-Polinomios!$F$7)/40 -> 138 | H10: =(Polinomios!$B$7+Polinomios!$C$7*G10+Polinomios!$D$7*G10^2+Polinomios!$E$7*G10^3) -> 269.13671 | J10: =Polinomios!$F$8+5*(Polinomios!$G$8-Polinomios!$F$8)/40 -> 141.25 | K10: =(Polinomios!$B$8+Polinomios!$C$8*J10+Polinomios!$D$8*J10^2+Polinomios!$E$8*J10^3) -> 316.25637 | M10: =(Polinomios!$C$12+Polinomios!$D$12*N10+Polinomios!$E$12*N10^2+Polinomios!$F$12*N10^3) -> 308.31905 | N10: =Polinomios!$G$12+5*(Polinomios!$H$12-Polinomios!$G$12)/20 -> 181.1275 | P10: =(Polinomios!$C$13+Polinomios!$D$13*Q10+Polinomios!$E$13*Q10^2+Polinomios!$F$13*Q10^3) -> 376.54651 | Q10: =Polinomios!$G$13+5*(Polinomios!$H$13-Polinomios!$G$13)/20 -> 178.325 | S10: =(Polinomios!$C$14+Polinomios!$D$14*T10+Polinomios!$E$14*T10^2+Polinomios!$F$14*T10^3) -> 443.1991 | T10: =Polinomios!$G$14+5*(Polinomios!$H$14-Polinomios!$G$14)/20 -> 174.83 | V10: =(Polinomios!$C$15+Polinomios!$D$15*W10+Polinomios!$E$15*W10^2+Polinomios!$F$15*W10^3) -> 511.97956 | W10: =Polinomios!$G$15+5*(Polinomios!$H$15-Polinomios!$G$15)/20 -> 169.54 | Y10: =(Polinomios!$C$16+Polinomios!$D$16*Z10+Polinomios!$E$16*Z10^2+Polinomios!$F$16*Z10^3) -> 572.76858 | Z10: =Polinomios!$G$16+5*(Polinomios!$H$16-Polinomios!$G$16)/20 -> 163.64 | AB10: =(Polinomios!$C$17+Polinomios!$D$17*AC10+Polinomios!$E$17*AC10^2+Polinomios!$F$17*AC10^3) -> 624.60014 | AC10: =Polinomios!$G$17+5*(Polinomios!$H$17-Polinomios!$G$17)/20 -> 157.16 | AE10: =(Polinomios!$C$18+Polinomios!$D$18*AF10+Polinomios!$E$18*AF10^2+Polinomios!$F$18*AF10^3) -> 711.9726 | AF10: =Polinomios!$G$18+5*(Polinomios!$H$18-Polinomios!$G$18)/20 -> 187.5775 | AH10: =(Polinomios!$C$19+Polinomios!$D$19*AI10+Polinomios!$E$19*AI10^2+Polinomios!$F$19*AI10^3) -> 792.14304 | AI10: =Polinomios!$G$19+5*(Polinomios!$H$19-Polinomios!$G$19)/20 -> 181.265 | AK10: =(Polinomios!$C$20+Polinomios!$D$20*AL10+Polinomios!$E$20*AL10^2+Polinomios!$F$20*AL10^3) -> 760.42666 | AL10: =Polinomios!$G$20+5*(Polinomios!$H$20-Polinomios!$G$20)/20 -> 143.6625 | AN10: =(Polinomios!$C$21+Polinomios!$D$21*AO10+Polinomios!$E$21*AO10^2+Polinomios!$F$21*AO10^3) -> 785.8753 | AO10: =Polinomios!$G$21+5*(Polinomios!$H$21-Polinomios!$G$21)/20 -> 135.2675 | AQ10: =(Polinomios!$C$22+Polinomios!$D$22*AR10+Polinomios!$E$22*AR10^2+Polinomios!$F$22*AR10^3) -> 827.41982 | AR10: =Polinomios!$G$22+5*(Polinomios!$H$22-Polinomios!$G$22)/20 -> 126.1325 | AT10: =(Polinomios!$C$23+Polinomios!$D$23*AU10+Polinomios!$E$23*AU10^2+Polinomios!$F$23*AU10^3) -> 873.48307 | AU10: =Polinomios!$G$23+5*(Polinomios!$H$23-Polinomios!$G$23)/20 -> 114.6775 | AW10: =(Polinomios!$C$24+Polinomios!$D$24*AX10+Polinomios!$E$24*AX10^2+Polinomios!$F$24*AX10^3) -> 914.76217 | AX10: =Polinomios!$G$24+5*(Polinomios!$H$24-Polinomios!$G$24)/20 -> 100.97
A11: =Polinomios!$F$5+6*(Polinomios!$G$5-Polinomios!$F$5)/40 -> 127.5 | B11: =(Polinomios!$B$5+Polinomios!$C$5*A11+Polinomios!$D$5*A11^2+Polinomios!$E$5*A11^3) -> 157.59143 | D11: =Polinomios!$F$6+6*(Polinomios!$G$6-Polinomios!$F$6)/40 -> 146.25 | E11: =(Polinomios!$B$6+Polinomios!$C$6*D11+Polinomios!$D$6*D11^2+Polinomios!$E$6*D11^3) -> 216.96599 | G11: =Polinomios!$F$7+6*(Polinomios!$G$7-Polinomios!$F$7)/40 -> 165.6 | H11: =(Polinomios!$B$7+Polinomios!$C$7*G11+Polinomios!$D$7*G11^2+Polinomios!$E$7*G11^3) -> 268.44015 | J11: =Polinomios!$F$8+6*(Polinomios!$G$8-Polinomios!$F$8)/40 -> 169.5 | K11: =(Polinomios!$B$8+Polinomios!$C$8*J11+Polinomios!$D$8*J11^2+Polinomios!$E$8*J11^3) -> 315.43363 | M11: =(Polinomios!$C$12+Polinomios!$D$12*N11+Polinomios!$E$12*N11^2+Polinomios!$F$12*N11^3) -> 310.80484 | N11: =Polinomios!$G$12+6*(Polinomios!$H$12-Polinomios!$G$12)/20 -> 186.587 | P11: =(Polinomios!$C$13+Polinomios!$D$13*Q11+Polinomios!$E$13*Q11^2+Polinomios!$F$13*Q11^3) -> 378.45459 | Q11: =Polinomios!$G$13+6*(Polinomios!$H$13-Polinomios!$G$13)/20 -> 183.796 | S11: =(Polinomios!$C$14+Polinomios!$D$14*T11+Polinomios!$E$14*T11^2+Polinomios!$F$14*T11^3) -> 446.19813 | T11: =Polinomios!$G$14+6*(Polinomios!$H$14-Polinomios!$G$14)/20 -> 180.264 | V11: =(Polinomios!$C$15+Polinomios!$D$15*W11+Polinomios!$E$15*W11^2+Polinomios!$F$15*W11^3) -> 515.52404 | W11: =Polinomios!$G$15+6*(Polinomios!$H$15-Polinomios!$G$15)/20 -> 174.904 | Y11: =(Polinomios!$C$16+Polinomios!$D$16*Z11+Polinomios!$E$16*Z11^2+Polinomios!$F$16*Z11^3) -> 576.59431 | Z11: =Polinomios!$G$16+6*(Polinomios!$H$16-Polinomios!$G$16)/20 -> 168.958 | AB11: =(Polinomios!$C$17+Polinomios!$D$17*AC11+Polinomios!$E$17*AC11^2+Polinomios!$F$17*AC11^3) -> 627.34351 | AC11: =Polinomios!$G$17+6*(Polinomios!$H$17-Polinomios!$G$17)/20 -> 162.56 | AE11: =(Polinomios!$C$18+Polinomios!$D$18*AF11+Polinomios!$E$18*AF11^2+Polinomios!$F$18*AF11^3) -> 710.55476 | AF11: =Polinomios!$G$18+6*(Polinomios!$H$18-Polinomios!$G$18)/20 -> 190.693 | AH11: =(Polinomios!$C$19+Polinomios!$D$19*AI11+Polinomios!$E$19*AI11^2+Polinomios!$F$19*AI11^3) -> 801.55413 | AI11: =Polinomios!$G$19+6*(Polinomios!$H$19-Polinomios!$G$19)/20 -> 183.118 | AK11: =(Polinomios!$C$20+Polinomios!$D$20*AL11+Polinomios!$E$20*AL11^2+Polinomios!$F$20*AL11^3) -> 776.0987 | AL11: =Polinomios!$G$20+6*(Polinomios!$H$20-Polinomios!$G$20)/20 -> 147.427 | AN11: =(Polinomios!$C$21+Polinomios!$D$21*AO11+Polinomios!$E$21*AO11^2+Polinomios!$F$21*AO11^3) -> 799.72031 | AO11: =Polinomios!$G$21+6*(Polinomios!$H$21-Polinomios!$G$21)/20 -> 139.097 | AQ11: =(Polinomios!$C$22+Polinomios!$D$22*AR11+Polinomios!$E$22*AR11^2+Polinomios!$F$22*AR11^3) -> 841.69109 | AR11: =Polinomios!$G$22+6*(Polinomios!$H$22-Polinomios!$G$22)/20 -> 129.659 | AT11: =(Polinomios!$C$23+Polinomios!$D$23*AU11+Polinomios!$E$23*AU11^2+Polinomios!$F$23*AU11^3) -> 887.81656 | AU11: =Polinomios!$G$23+6*(Polinomios!$H$23-Polinomios!$G$23)/20 -> 117.709 | AW11: =(Polinomios!$C$24+Polinomios!$D$24*AX11+Polinomios!$E$24*AX11^2+Polinomios!$F$24*AX11^3) -> 927.75399 | AX11: =Polinomios!$G$24+6*(Polinomios!$H$24-Polinomios!$G$24)/20 -> 104.006
A12: =Polinomios!$F$5+7*(Polinomios!$G$5-Polinomios!$F$5)/40 -> 148.75 | B12: =(Polinomios!$B$5+Polinomios!$C$5*A12+Polinomios!$D$5*A12^2+Polinomios!$E$5*A12^3) -> 157.25913 | D12: =Polinomios!$F$6+7*(Polinomios!$G$6-Polinomios!$F$6)/40 -> 170.625 | E12: =(Polinomios!$B$6+Polinomios!$C$6*D12+Polinomios!$D$6*D12^2+Polinomios!$E$6*D12^3) -> 216.54385 | G12: =Polinomios!$F$7+7*(Polinomios!$G$7-Polinomios!$F$7)/40 -> 193.2 | H12: =(Polinomios!$B$7+Polinomios!$C$7*G12+Polinomios!$D$7*G12^2+Polinomios!$E$7*G12^3) -> 267.75843 | J12: =Polinomios!$F$8+7*(Polinomios!$G$8-Polinomios!$F$8)/40 -> 197.75 | K12: =(Polinomios!$B$8+Polinomios!$C$8*J12+Polinomios!$D$8*J12^2+Polinomios!$E$8*J12^3) -> 314.62782 | M12: =(Polinomios!$C$12+Polinomios!$D$12*N12+Polinomios!$E$12*N12^2+Polinomios!$F$12*N12^3) -> 313.42854 | N12: =Polinomios!$G$12+7*(Polinomios!$H$12-Polinomios!$G$12)/20 -> 192.0465 | P12: =(Polinomios!$C$13+Polinomios!$D$13*Q12+Polinomios!$E$13*Q12^2+Polinomios!$F$13*Q12^3) -> 380.54976 | Q12: =Polinomios!$G$13+7*(Polinomios!$H$13-Polinomios!$G$13)/20 -> 189.267 | S12: =(Polinomios!$C$14+Polinomios!$D$14*T12+Polinomios!$E$14*T12^2+Polinomios!$F$14*T12^3) -> 449.31346 | T12: =Polinomios!$G$14+7*(Polinomios!$H$14-Polinomios!$G$14)/20 -> 185.698 | V12: =(Polinomios!$C$15+Polinomios!$D$15*W12+Polinomios!$E$15*W12^2+Polinomios!$F$15*W12^3) -> 519.27548 | W12: =Polinomios!$G$15+7*(Polinomios!$H$15-Polinomios!$G$15)/20 -> 180.268 | Y12: =(Polinomios!$C$16+Polinomios!$D$16*Z12+Polinomios!$E$16*Z12^2+Polinomios!$F$16*Z12^3) -> 580.65645 | Z12: =Polinomios!$G$16+7*(Polinomios!$H$16-Polinomios!$G$16)/20 -> 174.276 | AB12: =(Polinomios!$C$17+Polinomios!$D$17*AC12+Polinomios!$E$17*AC12^2+Polinomios!$F$17*AC12^3) -> 630.41172 | AC12: =Polinomios!$G$17+7*(Polinomios!$H$17-Polinomios!$G$17)/20 -> 167.96 | AE12: =(Polinomios!$C$18+Polinomios!$D$18*AF12+Polinomios!$E$18*AF12^2+Polinomios!$F$18*AF12^3) -> 710.04248 | AF12: =Polinomios!$G$18+7*(Polinomios!$H$18-Polinomios!$G$18)/20 -> 193.8085 | AH12: =(Polinomios!$C$19+Polinomios!$D$19*AI12+Polinomios!$E$19*AI12^2+Polinomios!$F$19*AI12^3) -> 810.42607 | AI12: =Polinomios!$G$19+7*(Polinomios!$H$19-Polinomios!$G$19)/20 -> 184.971 | AK12: =(Polinomios!$C$20+Polinomios!$D$20*AL12+Polinomios!$E$20*AL12^2+Polinomios!$F$20*AL12^3) -> 790.29918 | AL12: =Polinomios!$G$20+7*(Polinomios!$H$20-Polinomios!$G$20)/20 -> 151.1915 | AN12: =(Polinomios!$C$21+Polinomios!$D$21*AO12+Polinomios!$E$21*AO12^2+Polinomios!$F$21*AO12^3) -> 813.06083 | AO12: =Polinomios!$G$21+7*(Polinomios!$H$21-Polinomios!$G$21)/20 -> 142.9265 | AQ12: =(Polinomios!$C$22+Polinomios!$D$22*AR12+Polinomios!$E$22*AR12^2+Polinomios!$F$22*AR12^3) -> 855.54996 | AR12: =Polinomios!$G$22+7*(Polinomios!$H$22-Polinomios!$G$22)/20 -> 133.1855 | AT12: =(Polinomios!$C$23+Polinomios!$D$23*AU12+Polinomios!$E$23*AU12^2+Polinomios!$F$23*AU12^3) -> 901.67598 | AU12: =Polinomios!$G$23+7*(Polinomios!$H$23-Polinomios!$G$23)/20 -> 120.7405 | AW12: =(Polinomios!$C$24+Polinomios!$D$24*AX12+Polinomios!$E$24*AX12^2+Polinomios!$F$24*AX12^3) -> 940.76388 | AX12: =Polinomios!$G$24+7*(Polinomios!$H$24-Polinomios!$G$24)/20 -> 107.042
A13: =Polinomios!$F$5+8*(Polinomios!$G$5-Polinomios!$F$5)/40 -> 170 | B13: =(Polinomios!$B$5+Polinomios!$C$5*A13+Polinomios!$D$5*A13^2+Polinomios!$E$5*A13^3) -> 156.90389 | D13: =Polinomios!$F$6+8*(Polinomios!$G$6-Polinomios!$F$6)/40 -> 195 | E13: =(Polinomios!$B$6+Polinomios!$C$6*D13+Polinomios!$D$6*D13^2+Polinomios!$E$6*D13^3) -> 216.11094 | G13: =Polinomios!$F$7+8*(Polinomios!$G$7-Polinomios!$F$7)/40 -> 220.8 | H13: =(Polinomios!$B$7+Polinomios!$C$7*G13+Polinomios!$D$7*G13^2+Polinomios!$E$7*G13^3) -> 267.07518 | J13: =Polinomios!$F$8+8*(Polinomios!$G$8-Polinomios!$F$8)/40 -> 226 | K13: =(Polinomios!$B$8+Polinomios!$C$8*J13+Polinomios!$D$8*J13^2+Polinomios!$E$8*J13^3) -> 313.81936 | M13: =(Polinomios!$C$12+Polinomios!$D$12*N13+Polinomios!$E$12*N13^2+Polinomios!$F$12*N13^3) -> 316.19015 | N13: =Polinomios!$G$12+8*(Polinomios!$H$12-Polinomios!$G$12)/20 -> 197.506 | P13: =(Polinomios!$C$13+Polinomios!$D$13*Q13+Polinomios!$E$13*Q13^2+Polinomios!$F$13*Q13^3) -> 382.83204 | Q13: =Polinomios!$G$13+8*(Polinomios!$H$13-Polinomios!$G$13)/20 -> 194.738 | S13: =(Polinomios!$C$14+Polinomios!$D$14*T13+Polinomios!$E$14*T13^2+Polinomios!$F$14*T13^3) -> 452.54509 | T13: =Polinomios!$G$14+8*(Polinomios!$H$14-Polinomios!$G$14)/20 -> 191.132 | V13: =(Polinomios!$C$15+Polinomios!$D$15*W13+Polinomios!$E$15*W13^2+Polinomios!$F$15*W13^3) -> 523.23387 | W13: =Polinomios!$G$15+8*(Polinomios!$H$15-Polinomios!$G$15)/20 -> 185.632 | Y13: =(Polinomios!$C$16+Polinomios!$D$16*Z13+Polinomios!$E$16*Z13^2+Polinomios!$F$16*Z13^3) -> 584.955 | Z13: =Polinomios!$G$16+8*(Polinomios!$H$16-Polinomios!$G$16)/20 -> 179.594 | AB13: =(Polinomios!$C$17+Polinomios!$D$17*AC13+Polinomios!$E$17*AC13^2+Polinomios!$F$17*AC13^3) -> 633.80477 | AC13: =Polinomios!$G$17+8*(Polinomios!$H$17-Polinomios!$G$17)/20 -> 173.36 | AE13: =(Polinomios!$C$18+Polinomios!$D$18*AF13+Polinomios!$E$18*AF13^2+Polinomios!$F$18*AF13^3) -> 710.31132 | AF13: =Polinomios!$G$18+8*(Polinomios!$H$18-Polinomios!$G$18)/20 -> 196.924 | AH13: =(Polinomios!$C$19+Polinomios!$D$19*AI13+Polinomios!$E$19*AI13^2+Polinomios!$F$19*AI13^3) -> 818.75886 | AI13: =Polinomios!$G$19+8*(Polinomios!$H$19-Polinomios!$G$19)/20 -> 186.824 | AK13: =(Polinomios!$C$20+Polinomios!$D$20*AL13+Polinomios!$E$20*AL13^2+Polinomios!$F$20*AL13^3) -> 803.19629 | AL13: =Polinomios!$G$20+8*(Polinomios!$H$20-Polinomios!$G$20)/20 -> 154.956 | AN13: =(Polinomios!$C$21+Polinomios!$D$21*AO13+Polinomios!$E$21*AO13^2+Polinomios!$F$21*AO13^3) -> 825.91435 | AO13: =Polinomios!$G$21+8*(Polinomios!$H$21-Polinomios!$G$21)/20 -> 146.756 | AQ13: =(Polinomios!$C$22+Polinomios!$D$22*AR13+Polinomios!$E$22*AR13^2+Polinomios!$F$22*AR13^3) -> 869.00137 | AR13: =Polinomios!$G$22+8*(Polinomios!$H$22-Polinomios!$G$22)/20 -> 136.712 | AT13: =(Polinomios!$C$23+Polinomios!$D$23*AU13+Polinomios!$E$23*AU13^2+Polinomios!$F$23*AU13^3) -> 915.11546 | AU13: =Polinomios!$G$23+8*(Polinomios!$H$23-Polinomios!$G$23)/20 -> 123.772 | AW13: =(Polinomios!$C$24+Polinomios!$D$24*AX13+Polinomios!$E$24*AX13^2+Polinomios!$F$24*AX13^3) -> 953.77542 | AX13: =Polinomios!$G$24+8*(Polinomios!$H$24-Polinomios!$G$24)/20 -> 110.078
A14: =Polinomios!$F$5+9*(Polinomios!$G$5-Polinomios!$F$5)/40 -> 191.25 | B14: =(Polinomios!$B$5+Polinomios!$C$5*A14+Polinomios!$D$5*A14^2+Polinomios!$E$5*A14^3) -> 156.51777 | D14: =Polinomios!$F$6+9*(Polinomios!$G$6-Polinomios!$F$6)/40 -> 219.375 | E14: =(Polinomios!$B$6+Polinomios!$C$6*D14+Polinomios!$D$6*D14^2+Polinomios!$E$6*D14^3) -> 215.65472 | G14: =Polinomios!$F$7+9*(Polinomios!$G$7-Polinomios!$F$7)/40 -> 248.4 | H14: =(Polinomios!$B$7+Polinomios!$C$7*G14+Polinomios!$D$7*G14^2+Polinomios!$E$7*G14^3) -> 266.37405 | J14: =Polinomios!$F$8+9*(Polinomios!$G$8-Polinomios!$F$8)/40 -> 254.25 | K14: =(Polinomios!$B$8+Polinomios!$C$8*J14+Polinomios!$D$8*J14^2+Polinomios!$E$8*J14^3) -> 312.98866 | M14: =(Polinomios!$C$12+Polinomios!$D$12*N14+Polinomios!$E$12*N14^2+Polinomios!$F$12*N14^3) -> 319.08968 | N14: =Polinomios!$G$12+9*(Polinomios!$H$12-Polinomios!$G$12)/20 -> 202.9655 | P14: =(Polinomios!$C$13+Polinomios!$D$13*Q14+Polinomios!$E$13*Q14^2+Polinomios!$F$13*Q14^3) -> 385.30141 | Q14: =Polinomios!$G$13+9*(Polinomios!$H$13-Polinomios!$G$13)/20 -> 200.209 | S14: =(Polinomios!$C$14+Polinomios!$D$14*T14+Polinomios!$E$14*T14^2+Polinomios!$F$14*T14^3) -> 455.893 | T14: =Polinomios!$G$14+9*(Polinomios!$H$14-Polinomios!$G$14)/20 -> 196.566 | V14: =(Polinomios!$C$15+Polinomios!$D$15*W14+Polinomios!$E$15*W14^2+Polinomios!$F$15*W14^3) -> 527.39921 | W14: =Polinomios!$G$15+9*(Polinomios!$H$15-Polinomios!$G$15)/20 -> 190.996 | Y14: =(Polinomios!$C$16+Polinomios!$D$16*Z14+Polinomios!$E$16*Z14^2+Polinomios!$F$16*Z14^3) -> 589.48996 | Z14: =Polinomios!$G$16+9*(Polinomios!$H$16-Polinomios!$G$16)/20 -> 184.912 | AB14: =(Polinomios!$C$17+Polinomios!$D$17*AC14+Polinomios!$E$17*AC14^2+Polinomios!$F$17*AC14^3) -> 637.52266 | AC14: =Polinomios!$G$17+9*(Polinomios!$H$17-Polinomios!$G$17)/20 -> 178.76 | AE14: =(Polinomios!$C$18+Polinomios!$D$18*AF14+Polinomios!$E$18*AF14^2+Polinomios!$F$18*AF14^3) -> 711.23687 | AF14: =Polinomios!$G$18+9*(Polinomios!$H$18-Polinomios!$G$18)/20 -> 200.0395 | AH14: =(Polinomios!$C$19+Polinomios!$D$19*AI14+Polinomios!$E$19*AI14^2+Polinomios!$F$19*AI14^3) -> 826.55249 | AI14: =Polinomios!$G$19+9*(Polinomios!$H$19-Polinomios!$G$19)/20 -> 188.677 | AK14: =(Polinomios!$C$20+Polinomios!$D$20*AL14+Polinomios!$E$20*AL14^2+Polinomios!$F$20*AL14^3) -> 814.95819 | AL14: =Polinomios!$G$20+9*(Polinomios!$H$20-Polinomios!$G$20)/20 -> 158.7205 | AN14: =(Polinomios!$C$21+Polinomios!$D$21*AO14+Polinomios!$E$21*AO14^2+Polinomios!$F$21*AO14^3) -> 838.29837 | AO14: =Polinomios!$G$21+9*(Polinomios!$H$21-Polinomios!$G$21)/20 -> 150.5855 | AQ14: =(Polinomios!$C$22+Polinomios!$D$22*AR14+Polinomios!$E$22*AR14^2+Polinomios!$F$22*AR14^3) -> 882.05028 | AR14: =Polinomios!$G$22+9*(Polinomios!$H$22-Polinomios!$G$22)/20 -> 140.2385 | AT14: =(Polinomios!$C$23+Polinomios!$D$23*AU14+Polinomios!$E$23*AU14^2+Polinomios!$F$23*AU14^3) -> 928.18917 | AU14: =Polinomios!$G$23+9*(Polinomios!$H$23-Polinomios!$G$23)/20 -> 126.8035 | AW14: =(Polinomios!$C$24+Polinomios!$D$24*AX14+Polinomios!$E$24*AX14^2+Polinomios!$F$24*AX14^3) -> 966.77223 | AX14: =Polinomios!$G$24+9*(Polinomios!$H$24-Polinomios!$G$24)/20 -> 113.114
A15: =Polinomios!$F$5+10*(Polinomios!$G$5-Polinomios!$F$5)/40 -> 212.5 | B15: =(Polinomios!$B$5+Polinomios!$C$5*A15+Polinomios!$D$5*A15^2+Polinomios!$E$5*A15^3) -> 156.09285 | D15: =Polinomios!$F$6+10*(Polinomios!$G$6-Polinomios!$F$6)/40 -> 243.75 | E15: =(Polinomios!$B$6+Polinomios!$C$6*D15+Polinomios!$D$6*D15^2+Polinomios!$E$6*D15^3) -> 215.16265 | G15: =Polinomios!$F$7+10*(Polinomios!$G$7-Polinomios!$F$7)/40 -> 276 | H15: =(Polinomios!$B$7+Polinomios!$C$7*G15+Polinomios!$D$7*G15^2+Polinomios!$E$7*G15^3) -> 265.63869 | J15: =Polinomios!$F$8+10*(Polinomios!$G$8-Polinomios!$F$8)/40 -> 282.5 | K15: =(Polinomios!$B$8+Polinomios!$C$8*J15+Polinomios!$D$8*J15^2+Polinomios!$E$8*J15^3) -> 312.11615 | M15: =(Polinomios!$C$12+Polinomios!$D$12*N15+Polinomios!$E$12*N15^2+Polinomios!$F$12*N15^3) -> 322.12712 | N15: =Polinomios!$G$12+10*(Polinomios!$H$12-Polinomios!$G$12)/20 -> 208.425 | P15: =(Polinomios!$C$13+Polinomios!$D$13*Q15+Polinomios!$E$13*Q15^2+Polinomios!$F$13*Q15^3) -> 387.95788 | Q15: =Polinomios!$G$13+10*(Polinomios!$H$13-Polinomios!$G$13)/20 -> 205.68 | S15: =(Polinomios!$C$14+Polinomios!$D$14*T15+Polinomios!$E$14*T15^2+Polinomios!$F$14*T15^3) -> 459.35722 | T15: =Polinomios!$G$14+10*(Polinomios!$H$14-Polinomios!$G$14)/20 -> 202 | V15: =(Polinomios!$C$15+Polinomios!$D$15*W15+Polinomios!$E$15*W15^2+Polinomios!$F$15*W15^3) -> 531.77152 | W15: =Polinomios!$G$15+10*(Polinomios!$H$15-Polinomios!$G$15)/20 -> 196.36 | Y15: =(Polinomios!$C$16+Polinomios!$D$16*Z15+Polinomios!$E$16*Z15^2+Polinomios!$F$16*Z15^3) -> 594.26133 | Z15: =Polinomios!$G$16+10*(Polinomios!$H$16-Polinomios!$G$16)/20 -> 190.23 | AB15: =(Polinomios!$C$17+Polinomios!$D$17*AC15+Polinomios!$E$17*AC15^2+Polinomios!$F$17*AC15^3) -> 641.5654 | AC15: =Polinomios!$G$17+10*(Polinomios!$H$17-Polinomios!$G$17)/20 -> 184.16 | AE15: =(Polinomios!$C$18+Polinomios!$D$18*AF15+Polinomios!$E$18*AF15^2+Polinomios!$F$18*AF15^3) -> 712.69471 | AF15: =Polinomios!$G$18+10*(Polinomios!$H$18-Polinomios!$G$18)/20 -> 203.155 | AH15: =(Polinomios!$C$19+Polinomios!$D$19*AI15+Polinomios!$E$19*AI15^2+Polinomios!$F$19*AI15^3) -> 833.80697 | AI15: =Polinomios!$G$19+10*(Polinomios!$H$19-Polinomios!$G$19)/20 -> 190.53 | AK15: =(Polinomios!$C$20+Polinomios!$D$20*AL15+Polinomios!$E$20*AL15^2+Polinomios!$F$20*AL15^3) -> 825.75307 | AL15: =Polinomios!$G$20+10*(Polinomios!$H$20-Polinomios!$G$20)/20 -> 162.485 | AN15: =(Polinomios!$C$21+Polinomios!$D$21*AO15+Polinomios!$E$21*AO15^2+Polinomios!$F$21*AO15^3) -> 850.23039 | AO15: =Polinomios!$G$21+10*(Polinomios!$H$21-Polinomios!$G$21)/20 -> 154.415 | AQ15: =(Polinomios!$C$22+Polinomios!$D$22*AR15+Polinomios!$E$22*AR15^2+Polinomios!$F$22*AR15^3) -> 894.70163 | AR15: =Polinomios!$G$22+10*(Polinomios!$H$22-Polinomios!$G$22)/20 -> 143.765 | AT15: =(Polinomios!$C$23+Polinomios!$D$23*AU15+Polinomios!$E$23*AU15^2+Polinomios!$F$23*AU15^3) -> 940.95126 | AU15: =Polinomios!$G$23+10*(Polinomios!$H$23-Polinomios!$G$23)/20 -> 129.835 | AW15: =(Polinomios!$C$24+Polinomios!$D$24*AX15+Polinomios!$E$24*AX15^2+Polinomios!$F$24*AX15^3) -> 979.7379 | AX15: =Polinomios!$G$24+10*(Polinomios!$H$24-Polinomios!$G$24)/20 -> 116.15
A16: =Polinomios!$F$5+11*(Polinomios!$G$5-Polinomios!$F$5)/40 -> 233.75 | B16: =(Polinomios!$B$5+Polinomios!$C$5*A16+Polinomios!$D$5*A16^2+Polinomios!$E$5*A16^3) -> 155.62119 | D16: =Polinomios!$F$6+11*(Polinomios!$G$6-Polinomios!$F$6)/40 -> 268.125 | E16: =(Polinomios!$B$6+Polinomios!$C$6*D16+Polinomios!$D$6*D16^2+Polinomios!$E$6*D16^3) -> 214.62219 | G16: =Polinomios!$F$7+11*(Polinomios!$G$7-Polinomios!$F$7)/40 -> 303.6 | H16: =(Polinomios!$B$7+Polinomios!$C$7*G16+Polinomios!$D$7*G16^2+Polinomios!$E$7*G16^3) -> 264.85274 | J16: =Polinomios!$F$8+11*(Polinomios!$G$8-Polinomios!$F$8)/40 -> 310.75 | K16: =(Polinomios!$B$8+Polinomios!$C$8*J16+Polinomios!$D$8*J16^2+Polinomios!$E$8*J16^3) -> 311.18224 | M16: =(Polinomios!$C$12+Polinomios!$D$12*N16+Polinomios!$E$12*N16^2+Polinomios!$F$12*N16^3) -> 325.30247 | N16: =Polinomios!$G$12+11*(Polinomios!$H$12-Polinomios!$G$12)/20 -> 213.8845 | P16: =(Polinomios!$C$13+Polinomios!$D$13*Q16+Polinomios!$E$13*Q16^2+Polinomios!$F$13*Q16^3) -> 390.80145 | Q16: =Polinomios!$G$13+11*(Polinomios!$H$13-Polinomios!$G$13)/20 -> 211.151 | S16: =(Polinomios!$C$14+Polinomios!$D$14*T16+Polinomios!$E$14*T16^2+Polinomios!$F$14*T16^3) -> 462.93773 | T16: =Polinomios!$G$14+11*(Polinomios!$H$14-Polinomios!$G$14)/20 -> 207.434 | V16: =(Polinomios!$C$15+Polinomios!$D$15*W16+Polinomios!$E$15*W16^2+Polinomios!$F$15*W16^3) -> 536.35078 | W16: =Polinomios!$G$15+11*(Polinomios!$H$15-Polinomios!$G$15)/20 -> 201.724 | Y16: =(Polinomios!$C$16+Polinomios!$D$16*Z16+Polinomios!$E$16*Z16^2+Polinomios!$F$16*Z16^3) -> 599.26912 | Z16: =Polinomios!$G$16+11*(Polinomios!$H$16-Polinomios!$G$16)/20 -> 195.548 | AB16: =(Polinomios!$C$17+Polinomios!$D$17*AC16+Polinomios!$E$17*AC16^2+Polinomios!$F$17*AC16^3) -> 645.93297 | AC16: =Polinomios!$G$17+11*(Polinomios!$H$17-Polinomios!$G$17)/20 -> 189.56 | AE16: =(Polinomios!$C$18+Polinomios!$D$18*AF16+Polinomios!$E$18*AF16^2+Polinomios!$F$18*AF16^3) -> 714.56041 | AF16: =Polinomios!$G$18+11*(Polinomios!$H$18-Polinomios!$G$18)/20 -> 206.2705 | AH16: =(Polinomios!$C$19+Polinomios!$D$19*AI16+Polinomios!$E$19*AI16^2+Polinomios!$F$19*AI16^3) -> 840.52229 | AI16: =Polinomios!$G$19+11*(Polinomios!$H$19-Polinomios!$G$19)/20 -> 192.383 | AK16: =(Polinomios!$C$20+Polinomios!$D$20*AL16+Polinomios!$E$20*AL16^2+Polinomios!$F$20*AL16^3) -> 835.74909 | AL16: =Polinomios!$G$20+11*(Polinomios!$H$20-Polinomios!$G$20)/20 -> 166.2495 | AN16: =(Polinomios!$C$21+Polinomios!$D$21*AO16+Polinomios!$E$21*AO16^2+Polinomios!$F$21*AO16^3) -> 861.72792 | AO16: =Polinomios!$G$21+11*(Polinomios!$H$21-Polinomios!$G$21)/20 -> 158.2445 | AQ16: =(Polinomios!$C$22+Polinomios!$D$22*AR16+Polinomios!$E$22*AR16^2+Polinomios!$F$22*AR16^3) -> 906.96036 | AR16: =Polinomios!$G$22+11*(Polinomios!$H$22-Polinomios!$G$22)/20 -> 147.2915 | AT16: =(Polinomios!$C$23+Polinomios!$D$23*AU16+Polinomios!$E$23*AU16^2+Polinomios!$F$23*AU16^3) -> 953.45586 | AU16: =Polinomios!$G$23+11*(Polinomios!$H$23-Polinomios!$G$23)/20 -> 132.8665 | AW16: =(Polinomios!$C$24+Polinomios!$D$24*AX16+Polinomios!$E$24*AX16^2+Polinomios!$F$24*AX16^3) -> 992.65606 | AX16: =Polinomios!$G$24+11*(Polinomios!$H$24-Polinomios!$G$24)/20 -> 119.186
